Workbook
Name __KDX3: [0]!__KDX3
Name __TTT1: #REF!
Name _A3: {#N/A,#N/A,FALSE,"단축1";#N/A,#N/A,FALSE,"단축2";#N/A,#N/A,FALSE,"단축3";#N/A,#N/A,FALSE,"장축";#N/A,#N/A,FALSE,"4WD"}
Name _KDX3: [0]!_KDX3
Name _Regression_Int: 1
Name _TCG04: [0]!_TCG04
Name _TTT1: #REF!
Name \a: #N/A
Name \b: #N/A
Name \z: #N/A
Name √: "SQRT"
Name a: '[1]5-1차수정'!#REF!
Name AAA: #REF!
Name AAAA: [0]!AAAA
Name AAAAA: [0]!AAAAA
Name AAAAAA: [0]!AAAAAA
Name AAAAAAAAA: [0]!AAAAAAAAA
Name AS: [0]!AS
Name ASDF: [0]!ASDF
Name ASDS: [0]!ASDS
Name btnReturn_click: [2]!btnReturn_click
Name btnReturn_click: [2]!btnReturn_click
Name btnReturn_click: [2]!btnReturn_click
Name btnReturn_click: [2]!btnReturn_click
Name btnReturn_click: [2]!btnReturn_click
Name btnReturn_click: [2]!btnReturn_click
Name btnReturn_click: [2]!btnReturn_click
Name btw_01: #REF!,#REF!,#REF!,#REF!,#REF!,#REF!,#REF!,#REF!,#REF!
Name btw_03: #REF!,#REF!,#REF!,#REF!,#REF!
Name CCCC: [0]!CCCC
Name EFSD: [0]!EFSD
Name FC: [0]!FC
Name FC_00: 0
Name FC_01: 70700
Name FC_02: 74700
Name FC_03: 76300
Name FC_04: 77700
Name FC_05: 78200
Name FC_06: 78300
Name FC_07: 3900+79200
Name FC_99: 0
Name FC현황: [0]!FC현황
Name FO_00: 56900
Name FO_01: 60800
Name FO_02: 68700
Name FO_03: 70200
Name FO_04: 69200
Name FO_05: 36300
Name FO_06: 0
Name FO_07: 0
Name FO_99: 23700
Name H: "Text 853"
Name HK: [0]!HK
Name HOCHING: [0]!HOCHING
Name IMPORT: #REF!
Name KJH: [0]!KJH
Name KK: [0]!KK
Name LANOS: #REF!
Name LC_00: 281000
Name LC_01: 258000

Sheet 파싱용
A1: 구분 | B1: 모델 | C1: 자재관리코드 | D1: 품명 | E1: 기능 및 용도 | F1: 소요량 | G1: 구매처 | H1: 비고
A2: 신조 | B2: HiNAS Navigation | C2: ='BOM_(신조) HiNAS Nav'!B11 -> SM0001 | D2: ='BOM_(신조) HiNAS Nav'!C11 -> Monitor | E2: ='BOM_(신조) HiNAS Nav'!E11 -> 27인치 모니터 | F2: ='BOM_(신조) HiNAS Nav'!I11 -> 1 | G2: ='BOM_(신조) HiNAS Nav'!M11 -> MRC/테트라다인 | H2: ='BOM_(신조) HiNAS Nav'!O11 -> RCU, RCU cable, RS485 cable, bracket 포함 | K2: 구 분 | L2: 완제품 코드 | M2: 구분 | N2: 모델 | P2: HiNAS 제품 시리얼 넘버 형식
C3: ='BOM_(신조) HiNAS Nav'!B12 -> SS0001 | D3: ='BOM_(신조) HiNAS Nav'!C12 -> Server | E3: ='BOM_(신조) HiNAS Nav'!E12 -> 메인 서버 | F3: ='BOM_(신조) HiNAS Nav'!I12 -> 1 | G3: ='BOM_(신조) HiNAS Nav'!M12 -> 테트라다인 | H3: ='BOM_(신조) HiNAS Nav'!O12 -> - | K3: 대형상선용 | L3: NS | M3: 신조 | N3: HiNAS Navigation | P3: 형식 | Q3: 완제품 코드-서버 납품연도-일련번호
C4: ='BOM_(신조) HiNAS Nav'!B13 -> SZ0013 | D4: ='BOM_(신조) HiNAS Nav'!C13 -> Trackball Mouse | E4: ='BOM_(신조) HiNAS Nav'!E13 -> 마우스 | F4: ='BOM_(신조) HiNAS Nav'!I13 -> 2 | G4: ='BOM_(신조) HiNAS Nav'!M13 -> 쿠팡 | H4: ='BOM_(신조) HiNAS Nav'!O13 -> - | L4: ND | M4: 신조 | N4: HiNAS Navigation DOM | P4: 서버 납품연도 | Q4: 26 (2026년)
C5: ='BOM_(신조) HiNAS Nav'!B14 -> SC0004 | D5: ='BOM_(신조) HiNAS Nav'!C14 -> NAS camera housing | E5: ='BOM_(신조) HiNAS Nav'!E14 -> 하우징 | F5: ='BOM_(신조) HiNAS Nav'!I14 -> 1 | G5: ='BOM_(신조) HiNAS Nav'!M14 -> MRC | H5: ='BOM_(신조) HiNAS Nav'!O14 -> - | L5: NB | M5: 신조 | N5: HiNAS Navigation DOM/ HiNAS SVM | P5: 일련번호 | Q5: 0001 부터 시작, 순차 증가
C6: ='BOM_(신조) HiNAS Nav'!B15 -> SC0010 | D6: ='BOM_(신조) HiNAS Nav'!C15 -> EO Camera | E6: ='BOM_(신조) HiNAS Nav'!E15 -> 광학 카메라(4K) | F6: ='BOM_(신조) HiNAS Nav'!I15 -> 3 | G6: ='BOM_(신조) HiNAS Nav'!M15 -> 사이더스/e-con | H6: ='BOM_(신조) HiNAS Nav'!O15 -> w. GMSL cable | L6: MS | M6: 신조 | N6: HiNAS Control | P6: 제품 코드 | Q6: BOM 기준
C7: ='BOM_(신조) HiNAS Nav'!B16 -> SC0002 | D7: ='BOM_(신조) HiNAS Nav'!C16 -> IR camera | E7: ='BOM_(신조) HiNAS Nav'!E16 -> 열화상 카메라 | F7: ='BOM_(신조) HiNAS Nav'!I16 -> 3 | G7: ='BOM_(신조) HiNAS Nav'!M16 -> IRKEN/FLIR | H7: ='BOM_(신조) HiNAS Nav'!O16 -> w. VPC KIT | L7: MD | M7: 신조 | N7: HiNAS Control/ HiNAS Navigation DOM
C8: ='BOM_(신조) HiNAS Nav'!B17 -> SC0003 | D8: ='BOM_(신조) HiNAS Nav'!C17 -> IR camera window | E8: ='BOM_(신조) HiNAS Nav'!E17 -> 열화상 카메라 윈도우 | F8: ='BOM_(신조) HiNAS Nav'!I17 -> 3 | G8: ='BOM_(신조) HiNAS Nav'!M17 -> 센서캠 | H8: ='BOM_(신조) HiNAS Nav'!O17 -> 1세대 용 (직경 42mm) | L8: MB | M8: 신조 | N8: HiNAS Control 2.0
C9: ='BOM_(신조) HiNAS Nav'!B18 -> SC0005 | D9: ='BOM_(신조) HiNAS Nav'!C18 -> NAS junction box | E9: ='BOM_(신조) HiNAS Nav'!E18 -> 정션박스 | F9: ='BOM_(신조) HiNAS Nav'!I18 -> 1 | G9: ='BOM_(신조) HiNAS Nav'!M18 -> MRC | H9: ='BOM_(신조) HiNAS Nav'!O18 -> - | L9: BS | M9: 신조 | N9: HiNAS SVM
C10: ='BOM_(신조) HiNAS Nav'!B19 -> SS0003 | D10: ='BOM_(신조) HiNAS Nav'!C19 -> Single Board Computer | E10: ='BOM_(신조) HiNAS Nav'!E19 -> 카메라와 서버 연동 | F10: ='BOM_(신조) HiNAS Nav'!I19 -> 1 | G10: ='BOM_(신조) HiNAS Nav'!M19 -> 사이더스/e-con | H10: ='BOM_(신조) HiNAS Nav'!O19 -> - | L10: BD | M10: 신조 | N10: HiNAS SVM/ HiNAS Navigation DOM
C11: ='BOM_(신조) HiNAS Nav'!B20 -> SZ0012 | D11: ='BOM_(신조) HiNAS Nav'!C20 -> SMPS | E11: ='BOM_(신조) HiNAS Nav'!E20 -> Single Board Computer 전원 공급 | F11: ='BOM_(신조) HiNAS Nav'!I20 -> 1 | G11: ='BOM_(신조) HiNAS Nav'!M20 -> 파워캅 | H11: ='BOM_(신조) HiNAS Nav'!O20 -> - | L11: RMS | M11: 개조 | N11: HiNAS Control
C12: ='BOM_(신조) HiNAS Nav'!B21 -> SZ0014 | D12: ='BOM_(신조) HiNAS Nav'!C21 -> EMI/EMC filter | E12: ='BOM_(신조) HiNAS Nav'!E21 -> 정션박스 전자파 차폐용 | F12: ='BOM_(신조) HiNAS Nav'!I21 -> 1 | G12: ='BOM_(신조) HiNAS Nav'!M21 -> 오키 | H12: ='BOM_(신조) HiNAS Nav'!O21 -> - | L12: RMB | M12: 개조 | N12: HiNAS Control/ HiNAS SVM
C13: ='BOM_(신조) HiNAS Nav'!B22 -> SB0002 | D13: ='BOM_(신조) HiNAS Nav'!C22 -> Network switch | E13: ='BOM_(신조) HiNAS Nav'!E22 -> 허브 (선급인증품) | F13: ='BOM_(신조) HiNAS Nav'!I22 -> 1 | G13: ='BOM_(신조) HiNAS Nav'!M22 -> 여의시스템 | H13: ='BOM_(신조) HiNAS Nav'!O22 -> - | L13: RBS | M13: 개조 | N13: HiNAS SVM
C14: ='BOM_(신조) HiNAS Nav'!B23 -> SE0003 | D14: ='BOM_(신조) HiNAS Nav'!C23 -> UPS | E14: ='BOM_(신조) HiNAS Nav'!E23 -> 1kVA, 무정전 전원 공급, Stand type | F14: ='BOM_(신조) HiNAS Nav'!I23 -> 1 | G14: ='BOM_(신조) HiNAS Nav'!M23 -> 기호티이에스 | H14: ='BOM_(신조) HiNAS Nav'!O23 -> 마린필터, network card, 케이블 포함
C15: ='BOM_(신조) HiNAS Nav'!B24 -> SZ0019 | D15: ='BOM_(신조) HiNAS Nav'!C24 -> 멀티탭 | E15: ='BOM_(신조) HiNAS Nav'!E24 -> UPS용 | F15: ='BOM_(신조) HiNAS Nav'!I24 -> 2 | G15: ='BOM_(신조) HiNAS Nav'!M24 -> 쿠팡 | H15: ='BOM_(신조) HiNAS Nav'!O24 -> -
C16: ='BOM_(신조) HiNAS Nav'!B25 -> SZ0020 | D16: ='BOM_(신조) HiNAS Nav'!C25 -> C13-C14(MALE) | E16: ='BOM_(신조) HiNAS Nav'!E25 -> UPS용 | F16: ='BOM_(신조) HiNAS Nav'!I25 -> 3 | G16: ='BOM_(신조) HiNAS Nav'!M25 -> 한주전자 | H16: ='BOM_(신조) HiNAS Nav'!O25 -> -
A17: 신조 | B17: HiNAS Navigation DOM | C17: ='BOM_(신조) HiNAS Nav DOM'!B11 -> SM0002 | D17: ='BOM_(신조) HiNAS Nav DOM'!C11 -> Monitor | E17: ='BOM_(신조) HiNAS Nav DOM'!E11 -> DOM 58.4인치 모니터 | F17: ='BOM_(신조) HiNAS Nav DOM'!I11 -> 1 | G17: ='BOM_(신조) HiNAS Nav DOM'!M11 -> MRC/테트라다인 | H17: ='BOM_(신조) HiNAS Nav DOM'!O11 -> RCU, RCU cable, RS485 cable, bracket 포함
C18: ='BOM_(신조) HiNAS Nav DOM'!B12 -> SS0001 | D18: ='BOM_(신조) HiNAS Nav DOM'!C12 -> Server | E18: ='BOM_(신조) HiNAS Nav DOM'!E12 -> 메인 서버 | F18: ='BOM_(신조) HiNAS Nav DOM'!I12 -> 1 | G18: ='BOM_(신조) HiNAS Nav DOM'!M12 -> 테트라다인 | H18: ='BOM_(신조) HiNAS Nav DOM'!O12 -> -
C19: ='BOM_(신조) HiNAS Nav DOM'!B13 -> SZ0013 | D19: ='BOM_(신조) HiNAS Nav DOM'!C13 -> Trackball Mouse | E19: ='BOM_(신조) HiNAS Nav DOM'!E13 -> 마우스 | F19: ='BOM_(신조) HiNAS Nav DOM'!I13 -> 2 | G19: ='BOM_(신조) HiNAS Nav DOM'!M13 -> 쿠팡 | H19: ='BOM_(신조) HiNAS Nav DOM'!O13 -> -
C20: ='BOM_(신조) HiNAS Nav DOM'!B14 -> SB0004 | D20: ='BOM_(신조) HiNAS Nav DOM'!C14 -> Firewall | E20: ='BOM_(신조) HiNAS Nav DOM'!E14 -> 방화벽 (선급인증품) | F20: ='BOM_(신조) HiNAS Nav DOM'!I14 -> 1 | G20: ='BOM_(신조) HiNAS Nav DOM'!M14 -> MRC | H20: ='BOM_(신조) HiNAS Nav DOM'!O14 -> -
C21: ='BOM_(신조) HiNAS Nav DOM'!B15 -> SB0002 | D21: ='BOM_(신조) HiNAS Nav DOM'!C15 -> Network switch | E21: ='BOM_(신조) HiNAS Nav DOM'!E15 -> 허브 (선급인증품) | F21: ='BOM_(신조) HiNAS Nav DOM'!I15 -> 1 | G21: ='BOM_(신조) HiNAS Nav DOM'!M15 -> 여의시스템 | H21: ='BOM_(신조) HiNAS Nav DOM'!O15 -> -
C22: ='BOM_(신조) HiNAS Nav DOM'!B16 -> SC0004 | D22: ='BOM_(신조) HiNAS Nav DOM'!C16 -> NAS camera housing | E22: ='BOM_(신조) HiNAS Nav DOM'!E16 -> 하우징 | F22: ='BOM_(신조) HiNAS Nav DOM'!I16 -> 1 | G22: ='BOM_(신조) HiNAS Nav DOM'!M16 -> MRC | H22: ='BOM_(신조) HiNAS Nav DOM'!O16 -> -
C23: ='BOM_(신조) HiNAS Nav DOM'!B17 -> SC0010 | D23: ='BOM_(신조) HiNAS Nav DOM'!C17 -> EO Camera | E23: ='BOM_(신조) HiNAS Nav DOM'!E17 -> 광학 카메라(4K) | F23: ='BOM_(신조) HiNAS Nav DOM'!I17 -> 3 | G23: ='BOM_(신조) HiNAS Nav DOM'!M17 -> 사이더스/e-con | H23: ='BOM_(신조) HiNAS Nav DOM'!O17 -> w. GMSL cable
C24: ='BOM_(신조) HiNAS Nav DOM'!B18 -> SC0002 | D24: ='BOM_(신조) HiNAS Nav DOM'!C18 -> IR camera | E24: ='BOM_(신조) HiNAS Nav DOM'!E18 -> 열화상 카메라 | F24: ='BOM_(신조) HiNAS Nav DOM'!I18 -> 3 | G24: ='BOM_(신조) HiNAS Nav DOM'!M18 -> IRKEN/FLIR | H24: ='BOM_(신조) HiNAS Nav DOM'!O18 -> w. VPC KIT
C25: ='BOM_(신조) HiNAS Nav DOM'!B19 -> SC0003 | D25: ='BOM_(신조) HiNAS Nav DOM'!C19 -> IR camera window | E25: ='BOM_(신조) HiNAS Nav DOM'!E19 -> 열화상 카메라 윈도우 | F25: ='BOM_(신조) HiNAS Nav DOM'!I19 -> 3 | G25: ='BOM_(신조) HiNAS Nav DOM'!M19 -> 센서캠 | H25: ='BOM_(신조) HiNAS Nav DOM'!O19 -> 1세대 용 (직경 42mm)
C26: ='BOM_(신조) HiNAS Nav DOM'!B20 -> SC0005 | D26: ='BOM_(신조) HiNAS Nav DOM'!C20 -> NAS junction box | E26: ='BOM_(신조) HiNAS Nav DOM'!E20 -> 정션박스 | F26: ='BOM_(신조) HiNAS Nav DOM'!I20 -> 1 | G26: ='BOM_(신조) HiNAS Nav DOM'!M20 -> MRC | H26: ='BOM_(신조) HiNAS Nav DOM'!O20 -> -
C27: ='BOM_(신조) HiNAS Nav DOM'!B21 -> SS0003 | D27: ='BOM_(신조) HiNAS Nav DOM'!C21 -> Single Board Computer | E27: ='BOM_(신조) HiNAS Nav DOM'!E21 -> 카메라와 서버 연동 | F27: ='BOM_(신조) HiNAS Nav DOM'!I21 -> 1 | G27: ='BOM_(신조) HiNAS Nav DOM'!M21 -> 사이더스/e-con | H27: ='BOM_(신조) HiNAS Nav DOM'!O21 -> -
C28: ='BOM_(신조) HiNAS Nav DOM'!B22 -> SZ0012 | D28: ='BOM_(신조) HiNAS Nav DOM'!C22 -> SMPS | E28: ='BOM_(신조) HiNAS Nav DOM'!E22 -> Single Board Computer 전원 공급 | F28: ='BOM_(신조) HiNAS Nav DOM'!I22 -> 1 | G28: ='BOM_(신조) HiNAS Nav DOM'!M22 -> 파워캅 | H28: ='BOM_(신조) HiNAS Nav DOM'!O22 -> -
C29: ='BOM_(신조) HiNAS Nav DOM'!B23 -> SZ0014 | D29: ='BOM_(신조) HiNAS Nav DOM'!C23 -> EMI/EMC filter | E29: ='BOM_(신조) HiNAS Nav DOM'!E23 -> 정션박스 전자파 차폐용 | F29: ='BOM_(신조) HiNAS Nav DOM'!I23 -> 1 | G29: ='BOM_(신조) HiNAS Nav DOM'!M23 -> 오키 | H29: ='BOM_(신조) HiNAS Nav DOM'!O23 -> -
... C32: ='BOM_(신조) HiNAS Nav DOM'!B26 -> SZ0020 | D32: ='BOM_(신조) HiNAS Nav DOM'!C26 -> C13-C14(MALE) | E32: ='BOM_(신조) HiNAS Nav DOM'!E26 -> UPS용 | F32: ='BOM_(신조) HiNAS Nav DOM'!I26 -> 3 | G32: ='BOM_(신조) HiNAS Nav DOM'!M26 -> 한주전자 | H32: ='BOM_(신조) HiNAS Nav DOM'!O26 -> -
A33: 신조 | B33: HiNAS Control | C33: ='BOM_(신조) HiNAS Control'!B11 -> SM0002 | D33: ='BOM_(신조) HiNAS Control'!C11 -> Monitor | E33: ='BOM_(신조) HiNAS Control'!E11 -> DOM 58.4인치 모니터 | F33: ='BOM_(신조) HiNAS Control'!I11 -> 1 | G33: ='BOM_(신조) HiNAS Control'!M11 -> MRC/테트라다인 | H33: ='BOM_(신조) HiNAS Control'!O11 -> RCU, RCU cable, RS485 cable, bracket 포함
C34: ='BOM_(신조) HiNAS Control'!B12 -> SM0003 | D34: ='BOM_(신조) HiNAS Control'!C12 -> Monitor | E34: ='BOM_(신조) HiNAS Control'!E12 -> 32인치 모니터 | F34: ='BOM_(신조) HiNAS Control'!I12 -> 1 | G34: ='BOM_(신조) HiNAS Control'!M12 -> MRC/테트라다인 | H34: ='BOM_(신조) HiNAS Control'!O12 -> RCU, RCU cable, RS485 cable, bracket 포함
C35: ='BOM_(신조) HiNAS Control'!B13 -> SS0001 | D35: ='BOM_(신조) HiNAS Control'!C13 -> Server | E35: ='BOM_(신조) HiNAS Control'!E13 -> 메인 서버 | F35: ='BOM_(신조) HiNAS Control'!I13 -> 2 | G35: ='BOM_(신조) HiNAS Control'!M13 -> 테트라다인 | H35: ='BOM_(신조) HiNAS Control'!O13 -> -
C36: ='BOM_(신조) HiNAS Control'!B14 -> SS0002 | D36: ='BOM_(신조) HiNAS Control'!C14 -> Client | E36: ='BOM_(신조) HiNAS Control'!E14 -> 클라이언트 서버 | F36: ='BOM_(신조) HiNAS Control'!I14 -> 2 | G36: ='BOM_(신조) HiNAS Control'!M14 -> 테트라다인 | H36: ='BOM_(신조) HiNAS Control'!O14 -> -
C37: ='BOM_(신조) HiNAS Control'!B15 -> SZ0006 | D37: ='BOM_(신조) HiNAS Control'!C15 -> Keyboard with trackball | E37: ='BOM_(신조) HiNAS Control'!E15 -> 선급인증품 | F37: ='BOM_(신조) HiNAS Control'!I15 -> 2 | G37: ='BOM_(신조) HiNAS Control'!M15 -> 피앤피컴포넌츠 | H37: ='BOM_(신조) HiNAS Control'!O15 -> panel mount / flush type
C38: ='BOM_(신조) HiNAS Control'!B16 -> SC0004 | D38: ='BOM_(신조) HiNAS Control'!C16 -> NAS camera housing | E38: ='BOM_(신조) HiNAS Control'!E16 -> 하우징 | F38: ='BOM_(신조) HiNAS Control'!I16 -> 1 | G38: ='BOM_(신조) HiNAS Control'!M16 -> MRC | H38: ='BOM_(신조) HiNAS Control'!O16 -> -
C39: ='BOM_(신조) HiNAS Control'!B17 -> SC0010 | D39: ='BOM_(신조) HiNAS Control'!C17 -> EO Camera | E39: ='BOM_(신조) HiNAS Control'!E17 -> 광학 카메라(4K) | F39: ='BOM_(신조) HiNAS Control'!I17 -> 3 | G39: ='BOM_(신조) HiNAS Control'!M17 -> 사이더스/e-con | H39: ='BOM_(신조) HiNAS Control'!O17 -> w. GMSL cable
C40: ='BOM_(신조) HiNAS Control'!B18 -> SC0002 | D40: ='BOM_(신조) HiNAS Control'!C18 -> IR camera | E40: ='BOM_(신조) HiNAS Control'!E18 -> 열화상 카메라 | F40: ='BOM_(신조) HiNAS Control'!I18 -> 3 | G40: ='BOM_(신조) HiNAS Control'!M18 -> IRKEN/FLIR | H40: ='BOM_(신조) HiNAS Control'!O18 -> w. VPC KIT
C41: ='BOM_(신조) HiNAS Control'!B19 -> SC0003 | D41: ='BOM_(신조) HiNAS Control'!C19 -> IR camera window | E41: ='BOM_(신조) HiNAS Control'!E19 -> 열화상 카메라 윈도우 | F41: ='BOM_(신조) HiNAS Control'!I19 -> 3 | G41: ='BOM_(신조) HiNAS Control'!M19 -> 센서캠 | H41: ='BOM_(신조) HiNAS Control'!O19 -> 1세대 용 (직경 42mm)
C42: ='BOM_(신조) HiNAS Control'!B20 -> SC0005 | D42: ='BOM_(신조) HiNAS Control'!C20 -> NAS junction box | E42: ='BOM_(신조) HiNAS Control'!E20 -> 정션박스 | F42: ='BOM_(신조) HiNAS Control'!I20 -> 1 | G42: ='BOM_(신조) HiNAS Control'!M20 -> MRC | H42: ='BOM_(신조) HiNAS Control'!O20 -> -
...

Sheet BOM_(신조) HiNAS Nav
A2: 소요부품(자재) 명세서(Bill of Materials)
A4: □ 완제품 품명 | C4: : | D4: (신조) HiNAS Navigation
A5: □ HS CODE | C5: : | D5: NS
A6: □ 적용협정 | C6: :
A7: □ 원산지결정기준 | C7: :
A8: □ 원자재 사용내역
A10: 연번 | B10: 자재관리코드 | C10: 품명(자재명) | E10: 기능 및 용도 | F10: 세번부호 (HS No) | G10: 원산지 | H10: 단위 | I10: 소요량 | J10: 통화 | K10: 단가 | L10: 가격 | M10: 구매처 | N10: 입증서류 | O10: 비고
A11: 1 | B11: SM0001 | C11: =IFERROR(VLOOKUP($B11,자재리스트!$B$4:$M$92,2,FALSE),) -> Monitor | E11: =IFERROR(VLOOKUP($B11,자재리스트!$B$4:$M$92,4,FALSE),) -> 27인치 모니터 | F11: =IFERROR(VLOOKUP($B11,자재리스트!$B$4:$M$92,5,FALSE),) -> - | G11: =IFERROR(VLOOKUP($B11,자재리스트!$B$4:$M$92,6,FALSE),) -> 한국 | H11: =IFERROR(VLOOKUP($B11,자재리스트!$B$4:$M$92,7,FALSE),) -> 개 | I11: 1 | J11: =IFERROR(VLOOKUP($B11,자재리스트!$B$4:$M$92,8,FALSE),) -> KRW | K11: =IFERROR(VLOOKUP($B11,자재리스트!$B$4:$M$92,9,FALSE),) -> 3020000 | L11: =I11*K11 -> 3020000 | M11: =IFERROR(VLOOKUP($B11,자재리스트!$B$4:$M$92,10,FALSE),) -> MRC/테트라다인 | N11: =IFERROR(VLOOKUP($B11,자재리스트!$B$4:$M$92,11,FALSE),) -> 거래명세서 | O11: =IFERROR(VLOOKUP($B11,자재리스트!$B$4:$M$92,12,FALSE),) -> RCU, RCU cable, RS485 cable, bracket 포함
A12: 2 | B12: SS0001 | C12: =IFERROR(VLOOKUP($B12,자재리스트!$B$4:$M$92,2,FALSE),) -> Server | E12: =IFERROR(VLOOKUP($B12,자재리스트!$B$4:$M$92,4,FALSE),) -> 메인 서버 | F12: =IFERROR(VLOOKUP($B12,자재리스트!$B$4:$M$92,5,FALSE),) -> - | G12: =IFERROR(VLOOKUP($B12,자재리스트!$B$4:$M$92,6,FALSE),) -> 중국 | H12: =IFERROR(VLOOKUP($B12,자재리스트!$B$4:$M$92,7,FALSE),) -> 개 | I12: 1 | J12: =IFERROR(VLOOKUP($B12,자재리스트!$B$4:$M$92,8,FALSE),) -> KRW | K12: =IFERROR(VLOOKUP($B12,자재리스트!$B$4:$M$92,9,FALSE),) -> 3320000 | L12: =I12*K12 -> 3320000 | M12: =IFERROR(VLOOKUP($B12,자재리스트!$B$4:$M$92,10,FALSE),) -> 테트라다인 | N12: =IFERROR(VLOOKUP($B12,자재리스트!$B$4:$M$92,11,FALSE),) -> 거래명세서 | O12: =IFERROR(VLOOKUP($B12,자재리스트!$B$4:$M$92,12,FALSE),) -> -
A13: 3 | B13: SZ0013 | C13: =IFERROR(VLOOKUP($B13,자재리스트!$B$4:$M$92,2,FALSE),) -> Trackball Mouse | E13: =IFERROR(VLOOKUP($B13,자재리스트!$B$4:$M$92,4,FALSE),) -> 마우스 | F13: =IFERROR(VLOOKUP($B13,자재리스트!$B$4:$M$92,5,FALSE),) -> - | G13: =IFERROR(VLOOKUP($B13,자재리스트!$B$4:$M$92,6,FALSE),) -> 한국 | H13: =IFERROR(VLOOKUP($B13,자재리스트!$B$4:$M$92,7,FALSE),) -> 개 | I13: 2 | J13: =IFERROR(VLOOKUP($B13,자재리스트!$B$4:$M$92,8,FALSE),) -> KRW | K13: =IFERROR(VLOOKUP($B13,자재리스트!$B$4:$M$92,9,FALSE),) -> 95000 | L13: =I13*K13 -> 190000 | M13: =IFERROR(VLOOKUP($B13,자재리스트!$B$4:$M$92,10,FALSE),) -> 쿠팡 | N13: =IFERROR(VLOOKUP($B13,자재리스트!$B$4:$M$92,11,FALSE),) -> 거래명세서 | O13: =IFERROR(VLOOKUP($B13,자재리스트!$B$4:$M$92,12,FALSE),) -> -
A14: 4 | B14: SC0004 | C14: =IFERROR(VLOOKUP($B14,자재리스트!$B$4:$M$92,2,FALSE),) -> NAS camera housing | E14: =IFERROR(VLOOKUP($B14,자재리스트!$B$4:$M$92,4,FALSE),) -> 하우징 | F14: =IFERROR(VLOOKUP($B14,자재리스트!$B$4:$M$92,5,FALSE),) -> - | G14: =IFERROR(VLOOKUP($B14,자재리스트!$B$4:$M$92,6,FALSE),) -> 한국 | H14: =IFERROR(VLOOKUP($B14,자재리스트!$B$4:$M$92,7,FALSE),) -> 개 | I14: 1 | J14: =IFERROR(VLOOKUP($B14,자재리스트!$B$4:$M$92,8,FALSE),) -> KRW | K14: =IFERROR(VLOOKUP($B14,자재리스트!$B$4:$M$92,9,FALSE),) -> 4300000 | L14: =I14*K14 -> 4300000 | M14: =IFERROR(VLOOKUP($B14,자재리스트!$B$4:$M$92,10,FALSE),) -> MRC | N14: =IFERROR(VLOOKUP($B14,자재리스트!$B$4:$M$92,11,FALSE),) -> 거래명세서 | O14: =IFERROR(VLOOKUP($B14,자재리스트!$B$4:$M$92,12,FALSE),) -> -
A15: 5 | B15: SC0010 | C15: =IFERROR(VLOOKUP($B15,자재리스트!$B$4:$M$92,2,FALSE),) -> EO Camera | E15: =IFERROR(VLOOKUP($B15,자재리스트!$B$4:$M$92,4,FALSE),) -> 광학 카메라(4K) | F15: =IFERROR(VLOOKUP($B15,자재리스트!$B$4:$M$92,5,FALSE),) -> - | G15: =IFERROR(VLOOKUP($B15,자재리스트!$B$4:$M$92,6,FALSE),) -> 인도 | H15: =IFERROR(VLOOKUP($B15,자재리스트!$B$4:$M$92,7,FALSE),) -> 개 | I15: 3 | J15: =IFERROR(VLOOKUP($B15,자재리스트!$B$4:$M$92,8,FALSE),) -> KRW | K15: =IFERROR(VLOOKUP($B15,자재리스트!$B$4:$M$92,9,FALSE),) -> 532576 | L15: =I15*K15 -> 1597728 | M15: =IFERROR(VLOOKUP($B15,자재리스트!$B$4:$M$92,10,FALSE),) -> 사이더스/e-con | N15: =IFERROR(VLOOKUP($B15,자재리스트!$B$4:$M$92,11,FALSE),) -> 거래명세서 | O15: =IFERROR(VLOOKUP($B15,자재리스트!$B$4:$M$92,12,FALSE),) -> w. GMSL cable
A16: 6 | B16: SC0002 | C16: =IFERROR(VLOOKUP($B16,자재리스트!$B$4:$M$92,2,FALSE),) -> IR camera | E16: =IFERROR(VLOOKUP($B16,자재리스트!$B$4:$M$92,4,FALSE),) -> 열화상 카메라 | F16: =IFERROR(VLOOKUP($B16,자재리스트!$B$4:$M$92,5,FALSE),) -> - | G16: =IFERROR(VLOOKUP($B16,자재리스트!$B$4:$M$92,6,FALSE),) -> 미국 | H16: =IFERROR(VLOOKUP($B16,자재리스트!$B$4:$M$92,7,FALSE),) -> 개 | I16: 3 | J16: =IFERROR(VLOOKUP($B16,자재리스트!$B$4:$M$92,8,FALSE),) -> KRW | K16: =IFERROR(VLOOKUP($B16,자재리스트!$B$4:$M$92,9,FALSE),) -> 2487523 | L16: =I16*K16 -> 7462569 | M16: =IFERROR(VLOOKUP($B16,자재리스트!$B$4:$M$92,10,FALSE),) -> IRKEN/FLIR | N16: =IFERROR(VLOOKUP($B16,자재리스트!$B$4:$M$92,11,FALSE),) -> 거래명세서 | O16: =IFERROR(VLOOKUP($B16,자재리스트!$B$4:$M$92,12,FALSE),) -> w. VPC KIT
A17: 7 | B17: SC0003 | C17: =IFERROR(VLOOKUP($B17,자재리스트!$B$4:$M$92,2,FALSE),) -> IR camera window | E17: =IFERROR(VLOOKUP($B17,자재리스트!$B$4:$M$92,4,FALSE),) -> 열화상 카메라 윈도우 | F17: =IFERROR(VLOOKUP($B17,자재리스트!$B$4:$M$92,5,FALSE),) -> - | G17: =IFERROR(VLOOKUP($B17,자재리스트!$B$4:$M$92,6,FALSE),) -> 중국 | H17: =IFERROR(VLOOKUP($B17,자재리스트!$B$4:$M$92,7,FALSE),) -> 개 | I17: 3 | J17: =IFERROR(VLOOKUP($B17,자재리스트!$B$4:$M$92,8,FALSE),) -> KRW | K17: =IFERROR(VLOOKUP($B17,자재리스트!$B$4:$M$92,9,FALSE),) -> 220965 | L17: =I17*K17 -> 662895 | M17: =IFERROR(VLOOKUP($B17,자재리스트!$B$4:$M$92,10,FALSE),) -> 센서캠 | N17: =IFERROR(VLOOKUP($B17,자재리스트!$B$4:$M$92,11,FALSE),) -> 거래명세서 | O17: =IFERROR(VLOOKUP($B17,자재리스트!$B$4:$M$92,12,FALSE),) -> 1세대 용 (직경 42mm)
A18: 8 | B18: SC0005 | C18: =IFERROR(VLOOKUP($B18,자재리스트!$B$4:$M$92,2,FALSE),) -> NAS junction box | E18: =IFERROR(VLOOKUP($B18,자재리스트!$B$4:$M$92,4,FALSE),) -> 정션박스 | F18: =IFERROR(VLOOKUP($B18,자재리스트!$B$4:$M$92,5,FALSE),) -> - | G18: =IFERROR(VLOOKUP($B18,자재리스트!$B$4:$M$92,6,FALSE),) -> 한국 | H18: =IFERROR(VLOOKUP($B18,자재리스트!$B$4:$M$92,7,FALSE),) -> 개 | I18: 1 | J18: =IFERROR(VLOOKUP($B18,자재리스트!$B$4:$M$92,8,FALSE),) -> KRW | K18: =IFERROR(VLOOKUP($B18,자재리스트!$B$4:$M$92,9,FALSE),) -> 1000000 | L18: =I18*K18 -> 1000000 | M18: =IFERROR(VLOOKUP($B18,자재리스트!$B$4:$M$92,10,FALSE),) -> MRC | N18: =IFERROR(VLOOKUP($B18,자재리스트!$B$4:$M$92,11,FALSE),) -> 거래명세서 | O18: =IFERROR(VLOOKUP($B18,자재리스트!$B$4:$M$92,12,FALSE),) -> -
A19: 9 | B19: SS0003 | C19: =IFERROR(VLOOKUP($B19,자재리스트!$B$4:$M$92,2,FALSE),) -> Single Board Computer | E19: =IFERROR(VLOOKUP($B19,자재리스트!$B$4:$M$92,4,FALSE),) -> 카메라와 서버 연동 | F19: =IFERROR(VLOOKUP($B19,자재리스트!$B$4:$M$92,5,FALSE),) -> - | G19: =IFERROR(VLOOKUP($B19,자재리스트!$B$4:$M$92,6,FALSE),) -> 인도 | H19: =IFERROR(VLOOKUP($B19,자재리스트!$B$4:$M$92,7,FALSE),) -> 개 | I19: 1 | J19: =IFERROR(VLOOKUP($B19,자재리스트!$B$4:$M$92,8,FALSE),) -> KRW | K19: =IFERROR(VLOOKUP($B19,자재리스트!$B$4:$M$92,9,FALSE),) -> 4508312 | L19: =I19*K19 -> 4508312 | M19: =IFERROR(VLOOKUP($B19,자재리스트!$B$4:$M$92,10,FALSE),) -> 사이더스/e-con | N19: =IFERROR(VLOOKUP($B19,자재리스트!$B$4:$M$92,11,FALSE),) -> 거래명세서 | O19: =IFERROR(VLOOKUP($B19,자재리스트!$B$4:$M$92,12,FALSE),) -> -
A20: 10 | B20: SZ0012 | C20: =IFERROR(VLOOKUP($B20,자재리스트!$B$4:$M$92,2,FALSE),) -> SMPS | E20: =IFERROR(VLOOKUP($B20,자재리스트!$B$4:$M$92,4,FALSE),) -> Single Board Computer 전원 공급 | F20: =IFERROR(VLOOKUP($B20,자재리스트!$B$4:$M$92,5,FALSE),) -> - | G20: =IFERROR(VLOOKUP($B20,자재리스트!$B$4:$M$92,6,FALSE),) -> 한국 | H20: =IFERROR(VLOOKUP($B20,자재리스트!$B$4:$M$92,7,FALSE),) -> 개 | I20: 1 | J20: =IFERROR(VLOOKUP($B20,자재리스트!$B$4:$M$92,8,FALSE),) -> KRW | K20: =IFERROR(VLOOKUP($B20,자재리스트!$B$4:$M$92,9,FALSE),) -> 150000 | L20: =I20*K20 -> 150000 | M20: =IFERROR(VLOOKUP($B20,자재리스트!$B$4:$M$92,10,FALSE),) -> 파워캅 | N20: =IFERROR(VLOOKUP($B20,자재리스트!$B$4:$M$92,11,FALSE),) -> 거래명세서 | O20: =IFERROR(VLOOKUP($B20,자재리스트!$B$4:$M$92,12,FALSE),) -> -
A21: 11 | B21: SZ0014 | C21: =IFERROR(VLOOKUP($B21,자재리스트!$B$4:$M$92,2,FALSE),) -> EMI/EMC filter | E21: =IFERROR(VLOOKUP($B21,자재리스트!$B$4:$M$92,4,FALSE),) -> 정션박스 전자파 차폐용 | F21: =IFERROR(VLOOKUP($B21,자재리스트!$B$4:$M$92,5,FALSE),) -> - | G21: =IFERROR(VLOOKUP($B21,자재리스트!$B$4:$M$92,6,FALSE),) -> 한국 | H21: =IFERROR(VLOOKUP($B21,자재리스트!$B$4:$M$92,7,FALSE),) -> 개 | I21: 1 | J21: =IFERROR(VLOOKUP($B21,자재리스트!$B$4:$M$92,8,FALSE),) -> KRW | K21: =IFERROR(VLOOKUP($B21,자재리스트!$B$4:$M$92,9,FALSE),) -> 77000 | L21: =I21*K21 -> 77000 | M21: =IFERROR(VLOOKUP($B21,자재리스트!$B$4:$M$92,10,FALSE),) -> 오키 | N21: =IFERROR(VLOOKUP($B21,자재리스트!$B$4:$M$92,11,FALSE),) -> 거래명세서 | O21: =IFERROR(VLOOKUP($B21,자재리스트!$B$4:$M$92,12,FALSE),) -> -
A22: 12 | B22: SB0002 | C22: =IFERROR(VLOOKUP($B22,자재리스트!$B$4:$M$92,2,FALSE),) -> Network switch | E22: =IFERROR(VLOOKUP($B22,자재리스트!$B$4:$M$92,4,FALSE),) -> 허브 (선급인증품) | F22: =IFERROR(VLOOKUP($B22,자재리스트!$B$4:$M$92,5,FALSE),) -> - | G22: =IFERROR(VLOOKUP($B22,자재리스트!$B$4:$M$92,6,FALSE),) -> 한국 | H22: =IFERROR(VLOOKUP($B22,자재리스트!$B$4:$M$92,7,FALSE),) -> 개 | I22: 1 | J22: =IFERROR(VLOOKUP($B22,자재리스트!$B$4:$M$92,8,FALSE),) -> KRW | K22: =IFERROR(VLOOKUP($B22,자재리스트!$B$4:$M$92,9,FALSE),) -> 1596000 | L22: =I22*K22 -> 1596000 | M22: =IFERROR(VLOOKUP($B22,자재리스트!$B$4:$M$92,10,FALSE),) -> 여의시스템 | N22: =IFERROR(VLOOKUP($B22,자재리스트!$B$4:$M$92,11,FALSE),) -> 거래명세서 | O22: =IFERROR(VLOOKUP($B22,자재리스트!$B$4:$M$92,12,FALSE),) -> -
... A25: 15 | B25: SZ0020 | C25: =IFERROR(VLOOKUP($B25,자재리스트!$B$4:$M$92,2,FALSE),) -> C13-C14(MALE) | E25: =IFERROR(VLOOKUP($B25,자재리스트!$B$4:$M$92,4,FALSE),) -> UPS용 | F25: =IFERROR(VLOOKUP($B25,자재리스트!$B$4:$M$92,5,FALSE),) -> - | G25: =IFERROR(VLOOKUP($B25,자재리스트!$B$4:$M$92,6,FALSE),) -> 한국 | H25: =IFERROR(VLOOKUP($B25,자재리스트!$B$4:$M$92,7,FALSE),) -> 개 | I25: 3 | J25: =IFERROR(VLOOKUP($B25,자재리스트!$B$4:$M$92,8,FALSE),) -> KRW | K25: =IFERROR(VLOOKUP($B25,자재리스트!$B$4:$M$92,9,FALSE),) -> 9900 | L25: =I25*K25 -> 29700 | M25: =IFERROR(VLOOKUP($B25,자재리스트!$B$4:$M$92,10,FALSE),) -> 한주전자 | N25: =IFERROR(VLOOKUP($B25,자재리스트!$B$4:$M$92,11,FALSE),) -> 거래명세서 | O25: =IFERROR(VLOOKUP($B25,자재리스트!$B$4:$M$92,12,FALSE),) -> -
C27: ※ 자유무역협정의 이행을 위한, 원산지 증명서 관련업무 제출을 위하여 작성, 확인합니다.
C28: 작성자: ( 서명 )

Sheet BOM_(신조) HiNAS Nav DOM
A2: 소요부품(자재) 명세서(Bill of Materials)
A4: □ 완제품 품명 | C4: : | D4: (신조) HiNAS Navigation/DOM
A5: □ HS CODE | C5: : | D5: ND
A6: □ 적용협정 | C6: :
A7: □ 원산지결정기준 | C7: :
A8: □ 원자재 사용내역
A10: 연번 | B10: 자재관리코드 | C10: 품명(자재명) | E10: 기능 및 용도 | F10: 세번부호 (HS No) | G10: 원산지 | H10: 단위 | I10: 소요량 | J10: 통화 | K10: 단가 | L10: 가격 | M10: 구매처 | N10: 입증서류 | O10: 비고
A11: 1 | B11: SM0002 | C11: =IFERROR(VLOOKUP($B11,자재리스트!$B$4:$M$92,2,FALSE),) -> Monitor | E11: =IFERROR(VLOOKUP($B11,자재리스트!$B$4:$M$92,4,FALSE),) -> DOM 58.4인치 모니터 | F11: =IFERROR(VLOOKUP($B11,자재리스트!$B$4:$M$92,5,FALSE),) -> - | G11: =IFERROR(VLOOKUP($B11,자재리스트!$B$4:$M$92,6,FALSE),) -> 한국 | H11: =IFERROR(VLOOKUP($B11,자재리스트!$B$4:$M$92,7,FALSE),) -> 개 | I11: 1 | J11: =IFERROR(VLOOKUP($B11,자재리스트!$B$4:$M$92,8,FALSE),) -> KRW | K11: =IFERROR(VLOOKUP($B11,자재리스트!$B$4:$M$92,9,FALSE),) -> 6540000 | L11: =I11*K11 -> 6540000 | M11: =IFERROR(VLOOKUP($B11,자재리스트!$B$4:$M$92,10,FALSE),) -> MRC/테트라다인 | N11: =IFERROR(VLOOKUP($B11,자재리스트!$B$4:$M$92,11,FALSE),) -> 거래명세서 | O11: =IFERROR(VLOOKUP($B11,자재리스트!$B$4:$M$92,12,FALSE),) -> RCU, RCU cable, RS485 cable, bracket 포함
A12: 2 | B12: SS0001 | C12: =IFERROR(VLOOKUP($B12,자재리스트!$B$4:$M$92,2,FALSE),) -> Server | E12: =IFERROR(VLOOKUP($B12,자재리스트!$B$4:$M$92,4,FALSE),) -> 메인 서버 | F12: =IFERROR(VLOOKUP($B12,자재리스트!$B$4:$M$92,5,FALSE),) -> - | G12: =IFERROR(VLOOKUP($B12,자재리스트!$B$4:$M$92,6,FALSE),) -> 중국 | H12: =IFERROR(VLOOKUP($B12,자재리스트!$B$4:$M$92,7,FALSE),) -> 개 | I12: 1 | J12: =IFERROR(VLOOKUP($B12,자재리스트!$B$4:$M$92,8,FALSE),) -> KRW | K12: =IFERROR(VLOOKUP($B12,자재리스트!$B$4:$M$92,9,FALSE),) -> 3320000 | L12: =I12*K12 -> 3320000 | M12: =IFERROR(VLOOKUP($B12,자재리스트!$B$4:$M$92,10,FALSE),) -> 테트라다인 | N12: =IFERROR(VLOOKUP($B12,자재리스트!$B$4:$M$92,11,FALSE),) -> 거래명세서 | O12: =IFERROR(VLOOKUP($B12,자재리스트!$B$4:$M$92,12,FALSE),) -> -
A13: 3 | B13: SZ0013 | C13: =IFERROR(VLOOKUP($B13,자재리스트!$B$4:$M$92,2,FALSE),) -> Trackball Mouse | E13: =IFERROR(VLOOKUP($B13,자재리스트!$B$4:$M$92,4,FALSE),) -> 마우스 | F13: =IFERROR(VLOOKUP($B13,자재리스트!$B$4:$M$92,5,FALSE),) -> - | G13: =IFERROR(VLOOKUP($B13,자재리스트!$B$4:$M$92,6,FALSE),) -> 한국 | H13: =IFERROR(VLOOKUP($B13,자재리스트!$B$4:$M$92,7,FALSE),) -> 개 | I13: 2 | J13: =IFERROR(VLOOKUP($B13,자재리스트!$B$4:$M$92,8,FALSE),) -> KRW | K13: =IFERROR(VLOOKUP($B13,자재리스트!$B$4:$M$92,9,FALSE),) -> 95000 | L13: =I13*K13 -> 190000 | M13: =IFERROR(VLOOKUP($B13,자재리스트!$B$4:$M$92,10,FALSE),) -> 쿠팡 | N13: =IFERROR(VLOOKUP($B13,자재리스트!$B$4:$M$92,11,FALSE),) -> 거래명세서 | O13: =IFERROR(VLOOKUP($B13,자재리스트!$B$4:$M$92,12,FALSE),) -> -
A14: 4 | B14: SB0004 | C14: =IFERROR(VLOOKUP($B14,자재리스트!$B$4:$M$92,2,FALSE),) -> Firewall | E14: =IFERROR(VLOOKUP($B14,자재리스트!$B$4:$M$92,4,FALSE),) -> 방화벽 (선급인증품) | F14: =IFERROR(VLOOKUP($B14,자재리스트!$B$4:$M$92,5,FALSE),) -> - | G14: =IFERROR(VLOOKUP($B14,자재리스트!$B$4:$M$92,6,FALSE),) -> 한국 | H14: =IFERROR(VLOOKUP($B14,자재리스트!$B$4:$M$92,7,FALSE),) -> 개 | I14: 1 | J14: =IFERROR(VLOOKUP($B14,자재리스트!$B$4:$M$92,8,FALSE),) -> KRW | K14: =IFERROR(VLOOKUP($B14,자재리스트!$B$4:$M$92,9,FALSE),) -> 3800000 | L14: =I14*K14 -> 3800000 | M14: =IFERROR(VLOOKUP($B14,자재리스트!$B$4:$M$92,10,FALSE),) -> MRC | N14: =IFERROR(VLOOKUP($B14,자재리스트!$B$4:$M$92,11,FALSE),) -> 거래명세서 | O14: =IFERROR(VLOOKUP($B14,자재리스트!$B$4:$M$92,12,FALSE),) -> -
A15: 5 | B15: SB0002 | C15: =IFERROR(VLOOKUP($B15,자재리스트!$B$4:$M$92,2,FALSE),) -> Network switch | E15: =IFERROR(VLOOKUP($B15,자재리스트!$B$4:$M$92,4,FALSE),) -> 허브 (선급인증품) | F15: =IFERROR(VLOOKUP($B15,자재리스트!$B$4:$M$92,5,FALSE),) -> - | G15: =IFERROR(VLOOKUP($B15,자재리스트!$B$4:$M$92,6,FALSE),) -> 한국 | H15: =IFERROR(VLOOKUP($B15,자재리스트!$B$4:$M$92,7,FALSE),) -> 개 | I15: 1 | J15: =IFERROR(VLOOKUP($B15,자재리스트!$B$4:$M$92,8,FALSE),) -> KRW | K15: =IFERROR(VLOOKUP($B15,자재리스트!$B$4:$M$92,9,FALSE),) -> 1596000 | L15: =I15*K15 -> 1596000 | M15: =IFERROR(VLOOKUP($B15,자재리스트!$B$4:$M$92,10,FALSE),) -> 여의시스템 | N15: =IFERROR(VLOOKUP($B15,자재리스트!$B$4:$M$92,11,FALSE),) -> 거래명세서 | O15: =IFERROR(VLOOKUP($B15,자재리스트!$B$4:$M$92,12,FALSE),) -> -
A16: 6 | B16: SC0004 | C16: =IFERROR(VLOOKUP($B16,자재리스트!$B$4:$M$92,2,FALSE),) -> NAS camera housing | E16: =IFERROR(VLOOKUP($B16,자재리스트!$B$4:$M$92,4,FALSE),) -> 하우징 | F16: =IFERROR(VLOOKUP($B16,자재리스트!$B$4:$M$92,5,FALSE),) -> - | G16: =IFERROR(VLOOKUP($B16,자재리스트!$B$4:$M$92,6,FALSE),) -> 한국 | H16: =IFERROR(VLOOKUP($B16,자재리스트!$B$4:$M$92,7,FALSE),) -> 개 | I16: 1 | J16: =IFERROR(VLOOKUP($B16,자재리스트!$B$4:$M$92,8,FALSE),) -> KRW | K16: =IFERROR(VLOOKUP($B16,자재리스트!$B$4:$M$92,9,FALSE),) -> 4300000 | L16: =I16*K16 -> 4300000 | M16: =IFERROR(VLOOKUP($B16,자재리스트!$B$4:$M$92,10,FALSE),) -> MRC | N16: =IFERROR(VLOOKUP($B16,자재리스트!$B$4:$M$92,11,FALSE),) -> 거래명세서 | O16: =IFERROR(VLOOKUP($B16,자재리스트!$B$4:$M$92,12,FALSE),) -> -
A17: 7 | B17: SC0010 | C17: =IFERROR(VLOOKUP($B17,자재리스트!$B$4:$M$92,2,FALSE),) -> EO Camera | E17: =IFERROR(VLOOKUP($B17,자재리스트!$B$4:$M$92,4,FALSE),) -> 광학 카메라(4K) | F17: =IFERROR(VLOOKUP($B17,자재리스트!$B$4:$M$92,5,FALSE),) -> - | G17: =IFERROR(VLOOKUP($B17,자재리스트!$B$4:$M$92,6,FALSE),) -> 인도 | H17: =IFERROR(VLOOKUP($B17,자재리스트!$B$4:$M$92,7,FALSE),) -> 개 | I17: 3 | J17: =IFERROR(VLOOKUP($B17,자재리스트!$B$4:$M$92,8,FALSE),) -> KRW | K17: =IFERROR(VLOOKUP($B17,자재리스트!$B$4:$M$92,9,FALSE),) -> 532576 | L17: =I17*K17 -> 1597728 | M17: =IFERROR(VLOOKUP($B17,자재리스트!$B$4:$M$92,10,FALSE),) -> 사이더스/e-con | N17: =IFERROR(VLOOKUP($B17,자재리스트!$B$4:$M$92,11,FALSE),) -> 거래명세서 | O17: =IFERROR(VLOOKUP($B17,자재리스트!$B$4:$M$92,12,FALSE),) -> w. GMSL cable
A18: 8 | B18: SC0002 | C18: =IFERROR(VLOOKUP($B18,자재리스트!$B$4:$M$92,2,FALSE),) -> IR camera | E18: =IFERROR(VLOOKUP($B18,자재리스트!$B$4:$M$92,4,FALSE),) -> 열화상 카메라 | F18: =IFERROR(VLOOKUP($B18,자재리스트!$B$4:$M$92,5,FALSE),) -> - | G18: =IFERROR(VLOOKUP($B18,자재리스트!$B$4:$M$92,6,FALSE),) -> 미국 | H18: =IFERROR(VLOOKUP($B18,자재리스트!$B$4:$M$92,7,FALSE),) -> 개 | I18: 3 | J18: =IFERROR(VLOOKUP($B18,자재리스트!$B$4:$M$92,8,FALSE),) -> KRW | K18: =IFERROR(VLOOKUP($B18,자재리스트!$B$4:$M$92,9,FALSE),) -> 2487523 | L18: =I18*K18 -> 7462569 | M18: =IFERROR(VLOOKUP($B18,자재리스트!$B$4:$M$92,10,FALSE),) -> IRKEN/FLIR | N18: =IFERROR(VLOOKUP($B18,자재리스트!$B$4:$M$92,11,FALSE),) -> 거래명세서 | O18: =IFERROR(VLOOKUP($B18,자재리스트!$B$4:$M$92,12,FALSE),) -> w. VPC KIT
A19: 9 | B19: SC0003 | C19: =IFERROR(VLOOKUP($B19,자재리스트!$B$4:$M$92,2,FALSE),) -> IR camera window | E19: =IFERROR(VLOOKUP($B19,자재리스트!$B$4:$M$92,4,FALSE),) -> 열화상 카메라 윈도우 | F19: =IFERROR(VLOOKUP($B19,자재리스트!$B$4:$M$92,5,FALSE),) -> - | G19: =IFERROR(VLOOKUP($B19,자재리스트!$B$4:$M$92,6,FALSE),) -> 중국 | H19: =IFERROR(VLOOKUP($B19,자재리스트!$B$4:$M$92,7,FALSE),) -> 개 | I19: 3 | J19: =IFERROR(VLOOKUP($B19,자재리스트!$B$4:$M$92,8,FALSE),) -> KRW | K19: =IFERROR(VLOOKUP($B19,자재리스트!$B$4:$M$92,9,FALSE),) -> 220965 | L19: =I19*K19 -> 662895 | M19: =IFERROR(VLOOKUP($B19,자재리스트!$B$4:$M$92,10,FALSE),) -> 센서캠 | N19: =IFERROR(VLOOKUP($B19,자재리스트!$B$4:$M$92,11,FALSE),) -> 거래명세서 | O19: =IFERROR(VLOOKUP($B19,자재리스트!$B$4:$M$92,12,FALSE),) -> 1세대 용 (직경 42mm)
A20: 10 | B20: SC0005 | C20: =IFERROR(VLOOKUP($B20,자재리스트!$B$4:$M$92,2,FALSE),) -> NAS junction box | E20: =IFERROR(VLOOKUP($B20,자재리스트!$B$4:$M$92,4,FALSE),) -> 정션박스 | F20: =IFERROR(VLOOKUP($B20,자재리스트!$B$4:$M$92,5,FALSE),) -> - | G20: =IFERROR(VLOOKUP($B20,자재리스트!$B$4:$M$92,6,FALSE),) -> 한국 | H20: =IFERROR(VLOOKUP($B20,자재리스트!$B$4:$M$92,7,FALSE),) -> 개 | I20: 1 | J20: =IFERROR(VLOOKUP($B20,자재리스트!$B$4:$M$92,8,FALSE),) -> KRW | K20: =IFERROR(VLOOKUP($B20,자재리스트!$B$4:$M$92,9,FALSE),) -> 1000000 | L20: =I20*K20 -> 1000000 | M20: =IFERROR(VLOOKUP($B20,자재리스트!$B$4:$M$92,10,FALSE),) -> MRC | N20: =IFERROR(VLOOKUP($B20,자재리스트!$B$4:$M$92,11,FALSE),) -> 거래명세서 | O20: =IFERROR(VLOOKUP($B20,자재리스트!$B$4:$M$92,12,FALSE),) -> -
A21: 11 | B21: SS0003 | C21: =IFERROR(VLOOKUP($B21,자재리스트!$B$4:$M$92,2,FALSE),) -> Single Board Computer | E21: =IFERROR(VLOOKUP($B21,자재리스트!$B$4:$M$92,4,FALSE),) -> 카메라와 서버 연동 | F21: =IFERROR(VLOOKUP($B21,자재리스트!$B$4:$M$92,5,FALSE),) -> - | G21: =IFERROR(VLOOKUP($B21,자재리스트!$B$4:$M$92,6,FALSE),) -> 인도 | H21: =IFERROR(VLOOKUP($B21,자재리스트!$B$4:$M$92,7,FALSE),) -> 개 | I21: 1 | J21: =IFERROR(VLOOKUP($B21,자재리스트!$B$4:$M$92,8,FALSE),) -> KRW | K21: =IFERROR(VLOOKUP($B21,자재리스트!$B$4:$M$92,9,FALSE),) -> 4508312 | L21: =I21*K21 -> 4508312 | M21: =IFERROR(VLOOKUP($B21,자재리스트!$B$4:$M$92,10,FALSE),) -> 사이더스/e-con | N21: =IFERROR(VLOOKUP($B21,자재리스트!$B$4:$M$92,11,FALSE),) -> 거래명세서 | O21: =IFERROR(VLOOKUP($B21,자재리스트!$B$4:$M$92,12,FALSE),) -> -
A22: 12 | B22: SZ0012 | C22: =IFERROR(VLOOKUP($B22,자재리스트!$B$4:$M$92,2,FALSE),) -> SMPS | E22: =IFERROR(VLOOKUP($B22,자재리스트!$B$4:$M$92,4,FALSE),) -> Single Board Computer 전원 공급 | F22: =IFERROR(VLOOKUP($B22,자재리스트!$B$4:$M$92,5,FALSE),) -> - | G22: =IFERROR(VLOOKUP($B22,자재리스트!$B$4:$M$92,6,FALSE),) -> 한국 | H22: =IFERROR(VLOOKUP($B22,자재리스트!$B$4:$M$92,7,FALSE),) -> 개 | I22: 1 | J22: =IFERROR(VLOOKUP($B22,자재리스트!$B$4:$M$92,8,FALSE),) -> KRW | K22: =IFERROR(VLOOKUP($B22,자재리스트!$B$4:$M$92,9,FALSE),) -> 150000 | L22: =I22*K22 -> 150000 | M22: =IFERROR(VLOOKUP($B22,자재리스트!$B$4:$M$92,10,FALSE),) -> 파워캅 | N22: =IFERROR(VLOOKUP($B22,자재리스트!$B$4:$M$92,11,FALSE),) -> 거래명세서 | O22: =IFERROR(VLOOKUP($B22,자재리스트!$B$4:$M$92,12,FALSE),) -> -
... A26: 16 | B26: SZ0020 | C26: =IFERROR(VLOOKUP($B26,자재리스트!$B$4:$M$92,2,FALSE),) -> C13-C14(MALE) | E26: =IFERROR(VLOOKUP($B26,자재리스트!$B$4:$M$92,4,FALSE),) -> UPS용 | F26: =IFERROR(VLOOKUP($B26,자재리스트!$B$4:$M$92,5,FALSE),) -> - | G26: =IFERROR(VLOOKUP($B26,자재리스트!$B$4:$M$92,6,FALSE),) -> 한국 | H26: =IFERROR(VLOOKUP($B26,자재리스트!$B$4:$M$92,7,FALSE),) -> 개 | I26: 3 | J26: =IFERROR(VLOOKUP($B26,자재리스트!$B$4:$M$92,8,FALSE),) -> KRW | K26: =IFERROR(VLOOKUP($B26,자재리스트!$B$4:$M$92,9,FALSE),) -> 9900 | L26: =I26*K26 -> 29700 | M26: =IFERROR(VLOOKUP($B26,자재리스트!$B$4:$M$92,10,FALSE),) -> 한주전자 | N26: =IFERROR(VLOOKUP($B26,자재리스트!$B$4:$M$92,11,FALSE),) -> 거래명세서 | O26: =IFERROR(VLOOKUP($B26,자재리스트!$B$4:$M$92,12,FALSE),) -> -
C28: ※ 자유무역협정의 이행을 위한, 원산지 증명서 관련업무 제출을 위하여 작성, 확인합니다.
C29: 작성자: ( 서명 )

Sheet BOM_(신조) HiNAS Control
A2: 소요부품(자재) 명세서(Bill of Materials)
A4: □ 완제품 품명 | C4: : | D4: HiNAS Control
A5: □ HS CODE | C5: :
A6: □ 적용협정 | C6: :
A7: □ 원산지결정기준 | C7: :
A8: □ 원자재 사용내역
A10: 연번 | B10: 자재관리코드 | C10: 품명(자재명) | E10: 기능 및 용도 | F10: 세번부호 (HS No) | G10: 원산지 | H10: 단위 | I10: 소요량 | J10: 통화 | K10: 단가 | L10: 가격 | M10: 구매처 | N10: 입증서류 | O10: 비고
A11: 1 | B11: SM0002 | C11: =IFERROR(VLOOKUP($B11,자재리스트!$B$4:$M$92,2,FALSE),) -> Monitor | E11: =IFERROR(VLOOKUP($B11,자재리스트!$B$4:$M$92,4,FALSE),) -> DOM 58.4인치 모니터 | F11: =IFERROR(VLOOKUP($B11,자재리스트!$B$4:$M$92,5,FALSE),) -> - | G11: =IFERROR(VLOOKUP($B11,자재리스트!$B$4:$M$92,6,FALSE),) -> 한국 | H11: =IFERROR(VLOOKUP($B11,자재리스트!$B$4:$M$92,7,FALSE),) -> 개 | I11: 1 | J11: =IFERROR(VLOOKUP($B11,자재리스트!$B$4:$M$92,8,FALSE),) -> KRW | K11: =IFERROR(VLOOKUP($B11,자재리스트!$B$4:$M$92,9,FALSE),) -> 6540000 | L11: =I11*K11 -> 6540000 | M11: =IFERROR(VLOOKUP($B11,자재리스트!$B$4:$M$92,10,FALSE),) -> MRC/테트라다인 | N11: =IFERROR(VLOOKUP($B11,자재리스트!$B$4:$M$92,11,FALSE),) -> 거래명세서 | O11: =IFERROR(VLOOKUP($B11,자재리스트!$B$4:$M$92,12,FALSE),) -> RCU, RCU cable, RS485 cable, bracket 포함
A12: 2 | B12: SM0003 | C12: =IFERROR(VLOOKUP($B12,자재리스트!$B$4:$M$92,2,FALSE),) -> Monitor | E12: =IFERROR(VLOOKUP($B12,자재리스트!$B$4:$M$92,4,FALSE),) -> 32인치 모니터 | F12: =IFERROR(VLOOKUP($B12,자재리스트!$B$4:$M$92,5,FALSE),) -> - | G12: =IFERROR(VLOOKUP($B12,자재리스트!$B$4:$M$92,6,FALSE),) -> 한국 | H12: =IFERROR(VLOOKUP($B12,자재리스트!$B$4:$M$92,7,FALSE),) -> 개 | I12: 1 | J12: =IFERROR(VLOOKUP($B12,자재리스트!$B$4:$M$92,8,FALSE),) -> KRW | K12: =IFERROR(VLOOKUP($B12,자재리스트!$B$4:$M$92,9,FALSE),) -> 4480000 | L12: =I12*K12 -> 4480000 | M12: =IFERROR(VLOOKUP($B12,자재리스트!$B$4:$M$92,10,FALSE),) -> MRC/테트라다인 | N12: =IFERROR(VLOOKUP($B12,자재리스트!$B$4:$M$92,11,FALSE),) -> 거래명세서 | O12: =IFERROR(VLOOKUP($B12,자재리스트!$B$4:$M$92,12,FALSE),) -> RCU, RCU cable, RS485 cable, bracket 포함
A13: 3 | B13: SS0001 | C13: =IFERROR(VLOOKUP($B13,자재리스트!$B$4:$M$92,2,FALSE),) -> Server | E13: =IFERROR(VLOOKUP($B13,자재리스트!$B$4:$M$92,4,FALSE),) -> 메인 서버 | F13: =IFERROR(VLOOKUP($B13,자재리스트!$B$4:$M$92,5,FALSE),) -> - | G13: =IFERROR(VLOOKUP($B13,자재리스트!$B$4:$M$92,6,FALSE),) -> 중국 | H13: =IFERROR(VLOOKUP($B13,자재리스트!$B$4:$M$92,7,FALSE),) -> 개 | I13: 2 | J13: =IFERROR(VLOOKUP($B13,자재리스트!$B$4:$M$92,8,FALSE),) -> KRW | K13: =IFERROR(VLOOKUP($B13,자재리스트!$B$4:$M$92,9,FALSE),) -> 3320000 | L13: =I13*K13 -> 6640000 | M13: =IFERROR(VLOOKUP($B13,자재리스트!$B$4:$M$92,10,FALSE),) -> 테트라다인 | N13: =IFERROR(VLOOKUP($B13,자재리스트!$B$4:$M$92,11,FALSE),) -> 거래명세서 | O13: =IFERROR(VLOOKUP($B13,자재리스트!$B$4:$M$92,12,FALSE),) -> - | S13: 2800000
A14: 4 | B14: SS0002 | C14: =IFERROR(VLOOKUP($B14,자재리스트!$B$4:$M$92,2,FALSE),) -> Client | E14: =IFERROR(VLOOKUP($B14,자재리스트!$B$4:$M$92,4,FALSE),) -> 클라이언트 서버 | F14: =IFERROR(VLOOKUP($B14,자재리스트!$B$4:$M$92,5,FALSE),) -> - | G14: =IFERROR(VLOOKUP($B14,자재리스트!$B$4:$M$92,6,FALSE),) -> 중국 | H14: =IFERROR(VLOOKUP($B14,자재리스트!$B$4:$M$92,7,FALSE),) -> 개 | I14: 2 | J14: =IFERROR(VLOOKUP($B14,자재리스트!$B$4:$M$92,8,FALSE),) -> KRW | K14: =IFERROR(VLOOKUP($B14,자재리스트!$B$4:$M$92,9,FALSE),) -> 1820000 | L14: =I14*K14 -> 3640000 | M14: =IFERROR(VLOOKUP($B14,자재리스트!$B$4:$M$92,10,FALSE),) -> 테트라다인 | N14: =IFERROR(VLOOKUP($B14,자재리스트!$B$4:$M$92,11,FALSE),) -> 거래명세서 | O14: =IFERROR(VLOOKUP($B14,자재리스트!$B$4:$M$92,12,FALSE),) -> - | S14: 1695000
A15: 5 | B15: SZ0006 | C15: =IFERROR(VLOOKUP($B15,자재리스트!$B$4:$M$92,2,FALSE),) -> Keyboard with trackball | E15: =IFERROR(VLOOKUP($B15,자재리스트!$B$4:$M$92,4,FALSE),) -> 선급인증품 | F15: =IFERROR(VLOOKUP($B15,자재리스트!$B$4:$M$92,5,FALSE),) -> - | G15: =IFERROR(VLOOKUP($B15,자재리스트!$B$4:$M$92,6,FALSE),) -> 한국 | H15: =IFERROR(VLOOKUP($B15,자재리스트!$B$4:$M$92,7,FALSE),) -> 세트 | I15: 2 | J15: =IFERROR(VLOOKUP($B15,자재리스트!$B$4:$M$92,8,FALSE),) -> KRW | K15: =IFERROR(VLOOKUP($B15,자재리스트!$B$4:$M$92,9,FALSE),) -> 1200000 | L15: =I15*K15 -> 2400000 | M15: =IFERROR(VLOOKUP($B15,자재리스트!$B$4:$M$92,10,FALSE),) -> 피앤피컴포넌츠 | N15: =IFERROR(VLOOKUP($B15,자재리스트!$B$4:$M$92,11,FALSE),) -> 거래명세서 | O15: =IFERROR(VLOOKUP($B15,자재리스트!$B$4:$M$92,12,FALSE),) -> panel mount / flush type | S15: 1100000
A16: 6 | B16: SC0004 | C16: =IFERROR(VLOOKUP($B16,자재리스트!$B$4:$M$92,2,FALSE),) -> NAS camera housing | E16: =IFERROR(VLOOKUP($B16,자재리스트!$B$4:$M$92,4,FALSE),) -> 하우징 | F16: =IFERROR(VLOOKUP($B16,자재리스트!$B$4:$M$92,5,FALSE),) -> - | G16: =IFERROR(VLOOKUP($B16,자재리스트!$B$4:$M$92,6,FALSE),) -> 한국 | H16: =IFERROR(VLOOKUP($B16,자재리스트!$B$4:$M$92,7,FALSE),) -> 개 | I16: 1 | J16: =IFERROR(VLOOKUP($B16,자재리스트!$B$4:$M$92,8,FALSE),) -> KRW | K16: =IFERROR(VLOOKUP($B16,자재리스트!$B$4:$M$92,9,FALSE),) -> 4300000 | L16: =I16*K16 -> 4300000 | M16: =IFERROR(VLOOKUP($B16,자재리스트!$B$4:$M$92,10,FALSE),) -> MRC | N16: =IFERROR(VLOOKUP($B16,자재리스트!$B$4:$M$92,11,FALSE),) -> 거래명세서 | O16: =IFERROR(VLOOKUP($B16,자재리스트!$B$4:$M$92,12,FALSE),) -> - | S16: =1082333+4000000 -> 5082333
A17: 7 | B17: SC0010 | C17: =IFERROR(VLOOKUP($B17,자재리스트!$B$4:$M$92,2,FALSE),) -> EO Camera | E17: =IFERROR(VLOOKUP($B17,자재리스트!$B$4:$M$92,4,FALSE),) -> 광학 카메라(4K) | F17: =IFERROR(VLOOKUP($B17,자재리스트!$B$4:$M$92,5,FALSE),) -> - | G17: =IFERROR(VLOOKUP($B17,자재리스트!$B$4:$M$92,6,FALSE),) -> 인도 | H17: =IFERROR(VLOOKUP($B17,자재리스트!$B$4:$M$92,7,FALSE),) -> 개 | I17: 3 | J17: =IFERROR(VLOOKUP($B17,자재리스트!$B$4:$M$92,8,FALSE),) -> KRW | K17: =IFERROR(VLOOKUP($B17,자재리스트!$B$4:$M$92,9,FALSE),) -> 532576 | L17: =I17*K17 -> 1597728 | M17: =IFERROR(VLOOKUP($B17,자재리스트!$B$4:$M$92,10,FALSE),) -> 사이더스/e-con | N17: =IFERROR(VLOOKUP($B17,자재리스트!$B$4:$M$92,11,FALSE),) -> 거래명세서 | O17: =IFERROR(VLOOKUP($B17,자재리스트!$B$4:$M$92,12,FALSE),) -> w. GMSL cable | S17: 3500000
A18: 8 | B18: SC0002 | C18: =IFERROR(VLOOKUP($B18,자재리스트!$B$4:$M$92,2,FALSE),) -> IR camera | E18: =IFERROR(VLOOKUP($B18,자재리스트!$B$4:$M$92,4,FALSE),) -> 열화상 카메라 | F18: =IFERROR(VLOOKUP($B18,자재리스트!$B$4:$M$92,5,FALSE),) -> - | G18: =IFERROR(VLOOKUP($B18,자재리스트!$B$4:$M$92,6,FALSE),) -> 미국 | H18: =IFERROR(VLOOKUP($B18,자재리스트!$B$4:$M$92,7,FALSE),) -> 개 | I18: 3 | J18: =IFERROR(VLOOKUP($B18,자재리스트!$B$4:$M$92,8,FALSE),) -> KRW | K18: =IFERROR(VLOOKUP($B18,자재리스트!$B$4:$M$92,9,FALSE),) -> 2487523 | L18: =I18*K18 -> 7462569 | M18: =IFERROR(VLOOKUP($B18,자재리스트!$B$4:$M$92,10,FALSE),) -> IRKEN/FLIR | N18: =IFERROR(VLOOKUP($B18,자재리스트!$B$4:$M$92,11,FALSE),) -> 거래명세서 | O18: =IFERROR(VLOOKUP($B18,자재리스트!$B$4:$M$92,12,FALSE),) -> w. VPC KIT | S18: 6700000
A19: 9 | B19: SC0003 | C19: =IFERROR(VLOOKUP($B19,자재리스트!$B$4:$M$92,2,FALSE),) -> IR camera window | E19: =IFERROR(VLOOKUP($B19,자재리스트!$B$4:$M$92,4,FALSE),) -> 열화상 카메라 윈도우 | F19: =IFERROR(VLOOKUP($B19,자재리스트!$B$4:$M$92,5,FALSE),) -> - | G19: =IFERROR(VLOOKUP($B19,자재리스트!$B$4:$M$92,6,FALSE),) -> 중국 | H19: =IFERROR(VLOOKUP($B19,자재리스트!$B$4:$M$92,7,FALSE),) -> 개 | I19: 3 | J19: =IFERROR(VLOOKUP($B19,자재리스트!$B$4:$M$92,8,FALSE),) -> KRW | K19: =IFERROR(VLOOKUP($B19,자재리스트!$B$4:$M$92,9,FALSE),) -> 220965 | L19: =I19*K19 -> 662895 | M19: =IFERROR(VLOOKUP($B19,자재리스트!$B$4:$M$92,10,FALSE),) -> 센서캠 | N19: =IFERROR(VLOOKUP($B19,자재리스트!$B$4:$M$92,11,FALSE),) -> 거래명세서 | O19: =IFERROR(VLOOKUP($B19,자재리스트!$B$4:$M$92,12,FALSE),) -> 1세대 용 (직경 42mm) | S19: 2213000
A20: 10 | B20: SC0005 | C20: =IFERROR(VLOOKUP($B20,자재리스트!$B$4:$M$92,2,FALSE),) -> NAS junction box | E20: =IFERROR(VLOOKUP($B20,자재리스트!$B$4:$M$92,4,FALSE),) -> 정션박스 | F20: =IFERROR(VLOOKUP($B20,자재리스트!$B$4:$M$92,5,FALSE),) -> - | G20: =IFERROR(VLOOKUP($B20,자재리스트!$B$4:$M$92,6,FALSE),) -> 한국 | H20: =IFERROR(VLOOKUP($B20,자재리스트!$B$4:$M$92,7,FALSE),) -> 개 | I20: 1 | J20: =IFERROR(VLOOKUP($B20,자재리스트!$B$4:$M$92,8,FALSE),) -> KRW | K20: =IFERROR(VLOOKUP($B20,자재리스트!$B$4:$M$92,9,FALSE),) -> 1000000 | L20: =I20*K20 -> 1000000 | M20: =IFERROR(VLOOKUP($B20,자재리스트!$B$4:$M$92,10,FALSE),) -> MRC | N20: =IFERROR(VLOOKUP($B20,자재리스트!$B$4:$M$92,11,FALSE),) -> 거래명세서 | O20: =IFERROR(VLOOKUP($B20,자재리스트!$B$4:$M$92,12,FALSE),) -> - | S20: =1520000*2 -> 3040000
A21: 11 | B21: SS0003 | C21: =IFERROR(VLOOKUP($B21,자재리스트!$B$4:$M$92,2,FALSE),) -> Single Board Computer | E21: =IFERROR(VLOOKUP($B21,자재리스트!$B$4:$M$92,4,FALSE),) -> 카메라와 서버 연동 | F21: =IFERROR(VLOOKUP($B21,자재리스트!$B$4:$M$92,5,FALSE),) -> - | G21: =IFERROR(VLOOKUP($B21,자재리스트!$B$4:$M$92,6,FALSE),) -> 인도 | H21: =IFERROR(VLOOKUP($B21,자재리스트!$B$4:$M$92,7,FALSE),) -> 개 | I21: 1 | J21: =IFERROR(VLOOKUP($B21,자재리스트!$B$4:$M$92,8,FALSE),) -> KRW | K21: =IFERROR(VLOOKUP($B21,자재리스트!$B$4:$M$92,9,FALSE),) -> 4508312 | L21: =I21*K21 -> 4508312 | M21: =IFERROR(VLOOKUP($B21,자재리스트!$B$4:$M$92,10,FALSE),) -> 사이더스/e-con | N21: =IFERROR(VLOOKUP($B21,자재리스트!$B$4:$M$92,11,FALSE),) -> 거래명세서 | O21: =IFERROR(VLOOKUP($B21,자재리스트!$B$4:$M$92,12,FALSE),) -> - | S21: 1500000
A22: 12 | B22: SZ0012 | C22: =IFERROR(VLOOKUP($B22,자재리스트!$B$4:$M$92,2,FALSE),) -> SMPS | E22: =IFERROR(VLOOKUP($B22,자재리스트!$B$4:$M$92,4,FALSE),) -> Single Board Computer 전원 공급 | F22: =IFERROR(VLOOKUP($B22,자재리스트!$B$4:$M$92,5,FALSE),) -> - | G22: =IFERROR(VLOOKUP($B22,자재리스트!$B$4:$M$92,6,FALSE),) -> 한국 | H22: =IFERROR(VLOOKUP($B22,자재리스트!$B$4:$M$92,7,FALSE),) -> 개 | I22: 1 | J22: =IFERROR(VLOOKUP($B22,자재리스트!$B$4:$M$92,8,FALSE),) -> KRW | K22: =IFERROR(VLOOKUP($B22,자재리스트!$B$4:$M$92,9,FALSE),) -> 150000 | L22: =I22*K22 -> 150000 | M22: =IFERROR(VLOOKUP($B22,자재리스트!$B$4:$M$92,10,FALSE),) -> 파워캅 | N22: =IFERROR(VLOOKUP($B22,자재리스트!$B$4:$M$92,11,FALSE),) -> 거래명세서 | O22: =IFERROR(VLOOKUP($B22,자재리스트!$B$4:$M$92,12,FALSE),) -> - | S22: 3800000
A23: 13 | B23: SZ0014 | C23: =IFERROR(VLOOKUP($B23,자재리스트!$B$4:$M$92,2,FALSE),) -> EMI/EMC filter | E23: =IFERROR(VLOOKUP($B23,자재리스트!$B$4:$M$92,4,FALSE),) -> 정션박스 전자파 차폐용 | F23: =IFERROR(VLOOKUP($B23,자재리스트!$B$4:$M$92,5,FALSE),) -> - | G23: =IFERROR(VLOOKUP($B23,자재리스트!$B$4:$M$92,6,FALSE),) -> 한국 | H23: =IFERROR(VLOOKUP($B23,자재리스트!$B$4:$M$92,7,FALSE),) -> 개 | I23: 1 | J23: =IFERROR(VLOOKUP($B23,자재리스트!$B$4:$M$92,8,FALSE),) -> KRW | K23: =IFERROR(VLOOKUP($B23,자재리스트!$B$4:$M$92,9,FALSE),) -> 77000 | L23: =I23*K23 -> 77000 | M23: =IFERROR(VLOOKUP($B23,자재리스트!$B$4:$M$92,10,FALSE),) -> 오키 | N23: =IFERROR(VLOOKUP($B23,자재리스트!$B$4:$M$92,11,FALSE),) -> 거래명세서 | O23: =IFERROR(VLOOKUP($B23,자재리스트!$B$4:$M$92,12,FALSE),) -> - | S23: 28400000
A24: 14 | B24: SZ0007 | C24: =IFERROR(VLOOKUP($B24,자재리스트!$B$4:$M$92,2,FALSE),) -> Main rack | E24: =IFERROR(VLOOKUP($B24,자재리스트!$B$4:$M$92,4,FALSE),) -> 서버/HUB 등 설치용 Rack | F24: =IFERROR(VLOOKUP($B24,자재리스트!$B$4:$M$92,5,FALSE),) -> - | G24: =IFERROR(VLOOKUP($B24,자재리스트!$B$4:$M$92,6,FALSE),) -> 한국 | H24: =IFERROR(VLOOKUP($B24,자재리스트!$B$4:$M$92,7,FALSE),) -> 개 | I24: 1 | J24: =IFERROR(VLOOKUP($B24,자재리스트!$B$4:$M$92,8,FALSE),) -> KRW | K24: =IFERROR(VLOOKUP($B24,자재리스트!$B$4:$M$92,9,FALSE),) -> 3900000 | L24: =I24*K24 -> 3900000 | M24: =IFERROR(VLOOKUP($B24,자재리스트!$B$4:$M$92,10,FALSE),) -> MRC | N24: =IFERROR(VLOOKUP($B24,자재리스트!$B$4:$M$92,11,FALSE),) -> 거래명세서 | O24: =IFERROR(VLOOKUP($B24,자재리스트!$B$4:$M$92,12,FALSE),) -> -
A25: 15 | B25: SB0002 | C25: =IFERROR(VLOOKUP($B25,자재리스트!$B$4:$M$92,2,FALSE),) -> Network switch | E25: =IFERROR(VLOOKUP($B25,자재리스트!$B$4:$M$92,4,FALSE),) -> 허브 (선급인증품) | F25: =IFERROR(VLOOKUP($B25,자재리스트!$B$4:$M$92,5,FALSE),) -> - | G25: =IFERROR(VLOOKUP($B25,자재리스트!$B$4:$M$92,6,FALSE),) -> 한국 | H25: =IFERROR(VLOOKUP($B25,자재리스트!$B$4:$M$92,7,FALSE),) -> 개 | I25: 2 | J25: =IFERROR(VLOOKUP($B25,자재리스트!$B$4:$M$92,8,FALSE),) -> KRW | K25: =IFERROR(VLOOKUP($B25,자재리스트!$B$4:$M$92,9,FALSE),) -> 1596000 | L25: =I25*K25 -> 3192000 | M25: =IFERROR(VLOOKUP($B25,자재리스트!$B$4:$M$92,10,FALSE),) -> 여의시스템 | N25: =IFERROR(VLOOKUP($B25,자재리스트!$B$4:$M$92,11,FALSE),) -> 거래명세서 | O25: =IFERROR(VLOOKUP($B25,자재리스트!$B$4:$M$92,12,FALSE),) -> -
A26: 16 | B26: SB0006 | C26: =IFERROR(VLOOKUP($B26,자재리스트!$B$4:$M$92,2,FALSE),) -> Serial to Ethernet | E26: =IFERROR(VLOOKUP($B26,자재리스트!$B$4:$M$92,4,FALSE),) -> 시리얼 통신을 LAN으로 변환 | F26: =IFERROR(VLOOKUP($B26,자재리스트!$B$4:$M$92,5,FALSE),) -> - | G26: =IFERROR(VLOOKUP($B26,자재리스트!$B$4:$M$92,6,FALSE),) -> 한국 | H26: =IFERROR(VLOOKUP($B26,자재리스트!$B$4:$M$92,7,FALSE),) -> 개 | I26: 2 | J26: =IFERROR(VLOOKUP($B26,자재리스트!$B$4:$M$92,8,FALSE),) -> KRW | K26: =IFERROR(VLOOKUP($B26,자재리스트!$B$4:$M$92,9,FALSE),) -> 780000 | L26: =I26*K26 -> 1560000 | M26: =IFERROR(VLOOKUP($B26,자재리스트!$B$4:$M$92,10,FALSE),) -> 여의시스템 | N26: =IFERROR(VLOOKUP($B26,자재리스트!$B$4:$M$92,11,FALSE),) -> 거래명세서 | O26: =IFERROR(VLOOKUP($B26,자재리스트!$B$4:$M$92,12,FALSE),) -> -
A27: 17 | B27: SB0013 | C27: =IFERROR(VLOOKUP($B27,자재리스트!$B$4:$M$92,2,FALSE),) -> Actisense OPTO-4 | E27: =IFERROR(VLOOKUP($B27,자재리스트!$B$4:$M$92,4,FALSE),) -> MOXA NPort5450i 케이블 | F27: =IFERROR(VLOOKUP($B27,자재리스트!$B$4:$M$92,5,FALSE),) -> - | G27: =IFERROR(VLOOKUP($B27,자재리스트!$B$4:$M$92,6,FALSE),) -> 한국 | H27: =IFERROR(VLOOKUP($B27,자재리스트!$B$4:$M$92,7,FALSE),) -> 개 | I27: 4 | J27: =IFERROR(VLOOKUP($B27,자재리스트!$B$4:$M$92,8,FALSE),) -> KRW | K27: =IFERROR(VLOOKUP($B27,자재리스트!$B$4:$M$92,9,FALSE),) -> 120000 | L27: =I27*K27 -> 480000 | M27: =IFERROR(VLOOKUP($B27,자재리스트!$B$4:$M$92,10,FALSE),) -> 마린크래프트 | N27: =IFERROR(VLOOKUP($B27,자재리스트!$B$4:$M$92,11,FALSE),) -> 거래명세서 | O27: =IFERROR(VLOOKUP($B27,자재리스트!$B$4:$M$92,12,FALSE),) -> -
A28: 18 | B28: SB0004 | C28: =IFERROR(VLOOKUP($B28,자재리스트!$B$4:$M$92,2,FALSE),) -> Firewall | E28: =IFERROR(VLOOKUP($B28,자재리스트!$B$4:$M$92,4,FALSE),) -> 방화벽 (선급인증품) | F28: =IFERROR(VLOOKUP($B28,자재리스트!$B$4:$M$92,5,FALSE),) -> - | G28: =IFERROR(VLOOKUP($B28,자재리스트!$B$4:$M$92,6,FALSE),) -> 한국 | H28: =IFERROR(VLOOKUP($B28,자재리스트!$B$4:$M$92,7,FALSE),) -> 개 | I28: 1 | J28: =IFERROR(VLOOKUP($B28,자재리스트!$B$4:$M$92,8,FALSE),) -> KRW | K28: =IFERROR(VLOOKUP($B28,자재리스트!$B$4:$M$92,9,FALSE),) -> 3800000 | L28: =I28*K28 -> 3800000 | M28: =IFERROR(VLOOKUP($B28,자재리스트!$B$4:$M$92,10,FALSE),) -> MRC | N28: =IFERROR(VLOOKUP($B28,자재리스트!$B$4:$M$92,11,FALSE),) -> 거래명세서 | O28: =IFERROR(VLOOKUP($B28,자재리스트!$B$4:$M$92,12,FALSE),) -> -
A29: 19 | B29: SB0011 | C29: =IFERROR(VLOOKUP($B29,자재리스트!$B$4:$M$92,2,FALSE),) -> Selector Switch | E29: =IFERROR(VLOOKUP($B29,자재리스트!$B$4:$M$92,4,FALSE),) -> HiNAS control 선택 스위치 | F29: =IFERROR(VLOOKUP($B29,자재리스트!$B$4:$M$92,5,FALSE),) -> - | G29: =IFERROR(VLOOKUP($B29,자재리스트!$B$4:$M$92,6,FALSE),) -> 한국 | H29: =IFERROR(VLOOKUP($B29,자재리스트!$B$4:$M$92,7,FALSE),) -> 개 | I29: 1 | J29: =IFERROR(VLOOKUP($B29,자재리스트!$B$4:$M$92,8,FALSE),) -> USD | K29: =IFERROR(VLOOKUP($B29,자재리스트!$B$4:$M$92,9,FALSE),) -> 1330 | L29: =I29*K29 -> 1330 | M29: =IFERROR(VLOOKUP($B29,자재리스트!$B$4:$M$92,10,FALSE),) -> MRC/YDK | N29: =IFERROR(VLOOKUP($B29,자재리스트!$B$4:$M$92,11,FALSE),) -> 거래명세서 | O29: =IFERROR(VLOOKUP($B29,자재리스트!$B$4:$M$92,12,FALSE),) -> YOKOGAWA (w. DIMMER BOX)
A30: 20 | B30: SE0001 | C30: =IFERROR(VLOOKUP($B30,자재리스트!$B$4:$M$92,2,FALSE),) -> UPS | E30: =IFERROR(VLOOKUP($B30,자재리스트!$B$4:$M$92,4,FALSE),) -> 3kVA, 무정전 전원 공급, Rack type | F30: =IFERROR(VLOOKUP($B30,자재리스트!$B$4:$M$92,5,FALSE),) -> - | G30: =IFERROR(VLOOKUP($B30,자재리스트!$B$4:$M$92,6,FALSE),) -> 한국 | H30: =IFERROR(VLOOKUP($B30,자재리스트!$B$4:$M$92,7,FALSE),) -> 개 | I30: 1 | J30: =IFERROR(VLOOKUP($B30,자재리스트!$B$4:$M$92,8,FALSE),) -> KRW | K30: =IFERROR(VLOOKUP($B30,자재리스트!$B$4:$M$92,9,FALSE),) -> 2840000 | L30: =I30*K30 -> 2840000 | M30: =IFERROR(VLOOKUP($B30,자재리스트!$B$4:$M$92,10,FALSE),) -> 기호티이에스 | N30: =IFERROR(VLOOKUP($B30,자재리스트!$B$4:$M$92,11,FALSE),) -> 거래명세서 | O30: =IFERROR(VLOOKUP($B30,자재리스트!$B$4:$M$92,12,FALSE),) -> 마린필터, network card, 케이블 포함
A31: 21 | B31: SZ0019 | C31: =IFERROR(VLOOKUP($B31,자재리스트!$B$4:$M$92,2,FALSE),) -> 멀티탭 | E31: =IFERROR(VLOOKUP($B31,자재리스트!$B$4:$M$92,4,FALSE),) -> UPS용 | F31: =IFERROR(VLOOKUP($B31,자재리스트!$B$4:$M$92,5,FALSE),) -> - | G31: =IFERROR(VLOOKUP($B31,자재리스트!$B$4:$M$92,6,FALSE),) -> 한국 | H31: =IFERROR(VLOOKUP($B31,자재리스트!$B$4:$M$92,7,FALSE),) -> 개 | I31: 2 | J31: =IFERROR(VLOOKUP($B31,자재리스트!$B$4:$M$92,8,FALSE),) -> KRW | K31: =IFERROR(VLOOKUP($B31,자재리스트!$B$4:$M$92,9,FALSE),) -> 10800 | L31: =I31*K31 -> 21600 | M31: =IFERROR(VLOOKUP($B31,자재리스트!$B$4:$M$92,10,FALSE),) -> 쿠팡 | N31: =IFERROR(VLOOKUP($B31,자재리스트!$B$4:$M$92,11,FALSE),) -> 거래명세서 | O31: =IFERROR(VLOOKUP($B31,자재리스트!$B$4:$M$92,12,FALSE),) -> -
A32: 22 | B32: SZ0020 | C32: =IFERROR(VLOOKUP($B32,자재리스트!$B$4:$M$92,2,FALSE),) -> C13-C14(MALE) | E32: =IFERROR(VLOOKUP($B32,자재리스트!$B$4:$M$92,4,FALSE),) -> UPS용 | F32: =IFERROR(VLOOKUP($B32,자재리스트!$B$4:$M$92,5,FALSE),) -> - | G32: =IFERROR(VLOOKUP($B32,자재리스트!$B$4:$M$92,6,FALSE),) -> 한국 | H32: =IFERROR(VLOOKUP($B32,자재리스트!$B$4:$M$92,7,FALSE),) -> 개 | I32: 3 | J32: =IFERROR(VLOOKUP($B32,자재리스트!$B$4:$M$92,8,FALSE),) -> KRW | K32: =IFERROR(VLOOKUP($B32,자재리스트!$B$4:$M$92,9,FALSE),) -> 9900 | L32: =I32*K32 -> 29700 | M32: =IFERROR(VLOOKUP($B32,자재리스트!$B$4:$M$92,10,FALSE),) -> 한주전자 | N32: =IFERROR(VLOOKUP($B32,자재리스트!$B$4:$M$92,11,FALSE),) -> 거래명세서 | O32: =IFERROR(VLOOKUP($B32,자재리스트!$B$4:$M$92,12,FALSE),) -> -
C34: ※ 자유무역협정의 이행을 위한, 원산지 증명서 관련업무 제출을 위하여 작성, 확인합니다.
C35: 작성자: ( 서명 )

Sheet BOM_(신조) HiNAS Con V2
A2: 소요부품(자재) 명세서(Bill of Materials)
A4: □ 완제품 품명 | C4: : | D4: HiNAS Control
A5: □ HS CODE | C5: :
A6: □ 적용협정 | C6: :
A7: □ 원산지결정기준 | C7: :
A8: □ 원자재 사용내역
A10: 연번 | B10: 자재관리코드 | C10: 품명(자재명) | E10: 기능 및 용도 | F10: 세번부호 (HS No) | G10: 원산지 | H10: 단위 | I10: 소요량 | J10: 통화 | K10: 단가 | L10: 가격 | M10: 구매처 | N10: 입증서류 | O10: 비고
A11: 1 | B11: SM0002 | C11: =IFERROR(VLOOKUP($B11,자재리스트!$B$4:$M$92,2,FALSE),) -> Monitor | E11: =IFERROR(VLOOKUP($B11,자재리스트!$B$4:$M$92,4,FALSE),) -> DOM 58.4인치 모니터 | F11: =IFERROR(VLOOKUP($B11,자재리스트!$B$4:$M$92,5,FALSE),) -> - | G11: =IFERROR(VLOOKUP($B11,자재리스트!$B$4:$M$92,6,FALSE),) -> 한국 | H11: =IFERROR(VLOOKUP($B11,자재리스트!$B$4:$M$92,7,FALSE),) -> 개 | I11: 1 | J11: =IFERROR(VLOOKUP($B11,자재리스트!$B$4:$M$92,8,FALSE),) -> KRW | K11: =IFERROR(VLOOKUP($B11,자재리스트!$B$4:$M$92,9,FALSE),) -> 6540000 | L11: =I11*K11 -> 6540000 | M11: =IFERROR(VLOOKUP($B11,자재리스트!$B$4:$M$92,10,FALSE),) -> MRC/테트라다인 | N11: =IFERROR(VLOOKUP($B11,자재리스트!$B$4:$M$92,11,FALSE),) -> 거래명세서 | O11: =IFERROR(VLOOKUP($B11,자재리스트!$B$4:$M$92,12,FALSE),) -> RCU, RCU cable, RS485 cable, bracket 포함
A12: 2 | B12: SM0003 | C12: =IFERROR(VLOOKUP($B12,자재리스트!$B$4:$M$92,2,FALSE),) -> Monitor | E12: =IFERROR(VLOOKUP($B12,자재리스트!$B$4:$M$92,4,FALSE),) -> 32인치 모니터 | F12: =IFERROR(VLOOKUP($B12,자재리스트!$B$4:$M$92,5,FALSE),) -> - | G12: =IFERROR(VLOOKUP($B12,자재리스트!$B$4:$M$92,6,FALSE),) -> 한국 | H12: =IFERROR(VLOOKUP($B12,자재리스트!$B$4:$M$92,7,FALSE),) -> 개 | I12: 1 | J12: =IFERROR(VLOOKUP($B12,자재리스트!$B$4:$M$92,8,FALSE),) -> KRW | K12: =IFERROR(VLOOKUP($B12,자재리스트!$B$4:$M$92,9,FALSE),) -> 4480000 | L12: =I12*K12 -> 4480000 | M12: =IFERROR(VLOOKUP($B12,자재리스트!$B$4:$M$92,10,FALSE),) -> MRC/테트라다인 | N12: =IFERROR(VLOOKUP($B12,자재리스트!$B$4:$M$92,11,FALSE),) -> 거래명세서 | O12: =IFERROR(VLOOKUP($B12,자재리스트!$B$4:$M$92,12,FALSE),) -> RCU, RCU cable, RS485 cable, bracket 포함
A13: 3 | B13: SS0001 | C13: =IFERROR(VLOOKUP($B13,자재리스트!$B$4:$M$92,2,FALSE),) -> Server | E13: =IFERROR(VLOOKUP($B13,자재리스트!$B$4:$M$92,4,FALSE),) -> 메인 서버 | F13: =IFERROR(VLOOKUP($B13,자재리스트!$B$4:$M$92,5,FALSE),) -> - | G13: =IFERROR(VLOOKUP($B13,자재리스트!$B$4:$M$92,6,FALSE),) -> 중국 | H13: =IFERROR(VLOOKUP($B13,자재리스트!$B$4:$M$92,7,FALSE),) -> 개 | I13: 2 | J13: =IFERROR(VLOOKUP($B13,자재리스트!$B$4:$M$92,8,FALSE),) -> KRW | K13: =IFERROR(VLOOKUP($B13,자재리스트!$B$4:$M$92,9,FALSE),) -> 3320000 | L13: =I13*K13 -> 6640000 | M13: =IFERROR(VLOOKUP($B13,자재리스트!$B$4:$M$92,10,FALSE),) -> 테트라다인 | N13: =IFERROR(VLOOKUP($B13,자재리스트!$B$4:$M$92,11,FALSE),) -> 거래명세서 | O13: =IFERROR(VLOOKUP($B13,자재리스트!$B$4:$M$92,12,FALSE),) -> -
A14: 4 | B14: SS0002 | C14: =IFERROR(VLOOKUP($B14,자재리스트!$B$4:$M$92,2,FALSE),) -> Client | E14: =IFERROR(VLOOKUP($B14,자재리스트!$B$4:$M$92,4,FALSE),) -> 클라이언트 서버 | F14: =IFERROR(VLOOKUP($B14,자재리스트!$B$4:$M$92,5,FALSE),) -> - | G14: =IFERROR(VLOOKUP($B14,자재리스트!$B$4:$M$92,6,FALSE),) -> 중국 | H14: =IFERROR(VLOOKUP($B14,자재리스트!$B$4:$M$92,7,FALSE),) -> 개 | I14: 2 | J14: =IFERROR(VLOOKUP($B14,자재리스트!$B$4:$M$92,8,FALSE),) -> KRW | K14: =IFERROR(VLOOKUP($B14,자재리스트!$B$4:$M$92,9,FALSE),) -> 1820000 | L14: =I14*K14 -> 3640000 | M14: =IFERROR(VLOOKUP($B14,자재리스트!$B$4:$M$92,10,FALSE),) -> 테트라다인 | N14: =IFERROR(VLOOKUP($B14,자재리스트!$B$4:$M$92,11,FALSE),) -> 거래명세서 | O14: =IFERROR(VLOOKUP($B14,자재리스트!$B$4:$M$92,12,FALSE),) -> -
A15: 5 | B15: SZ0006 | C15: =IFERROR(VLOOKUP($B15,자재리스트!$B$4:$M$92,2,FALSE),) -> Keyboard with trackball | E15: =IFERROR(VLOOKUP($B15,자재리스트!$B$4:$M$92,4,FALSE),) -> 선급인증품 | F15: =IFERROR(VLOOKUP($B15,자재리스트!$B$4:$M$92,5,FALSE),) -> - | G15: =IFERROR(VLOOKUP($B15,자재리스트!$B$4:$M$92,6,FALSE),) -> 한국 | H15: =IFERROR(VLOOKUP($B15,자재리스트!$B$4:$M$92,7,FALSE),) -> 세트 | I15: 2 | J15: =IFERROR(VLOOKUP($B15,자재리스트!$B$4:$M$92,8,FALSE),) -> KRW | K15: =IFERROR(VLOOKUP($B15,자재리스트!$B$4:$M$92,9,FALSE),) -> 1200000 | L15: =I15*K15 -> 2400000 | M15: =IFERROR(VLOOKUP($B15,자재리스트!$B$4:$M$92,10,FALSE),) -> 피앤피컴포넌츠 | N15: =IFERROR(VLOOKUP($B15,자재리스트!$B$4:$M$92,11,FALSE),) -> 거래명세서 | O15: =IFERROR(VLOOKUP($B15,자재리스트!$B$4:$M$92,12,FALSE),) -> panel mount / flush type
A16: 6 | B16: SC0020 | C16: =IFERROR(VLOOKUP($B16,자재리스트!$B$4:$M$92,2,FALSE),) -> NAS camera housing | E16: =IFERROR(VLOOKUP($B16,자재리스트!$B$4:$M$92,4,FALSE),) -> 하우징 | F16: =IFERROR(VLOOKUP($B16,자재리스트!$B$4:$M$92,5,FALSE),) -> - | G16: =IFERROR(VLOOKUP($B16,자재리스트!$B$4:$M$92,6,FALSE),) -> 한국 | H16: =IFERROR(VLOOKUP($B16,자재리스트!$B$4:$M$92,7,FALSE),) -> 개 | I16: 1 | J16: =IFERROR(VLOOKUP($B16,자재리스트!$B$4:$M$92,8,FALSE),) -> KRW | K16: =IFERROR(VLOOKUP($B16,자재리스트!$B$4:$M$92,9,FALSE),) -> 4000000 | L16: =I16*K16 -> 4000000 | M16: =IFERROR(VLOOKUP($B16,자재리스트!$B$4:$M$92,10,FALSE),) -> MRC | N16: =IFERROR(VLOOKUP($B16,자재리스트!$B$4:$M$92,11,FALSE),) -> 거래명세서 | O16: =IFERROR(VLOOKUP($B16,자재리스트!$B$4:$M$92,12,FALSE),) -> -
A17: 7 | B17: SC0016 | C17: =IFERROR(VLOOKUP($B17,자재리스트!$B$4:$M$92,2,FALSE),) -> NAS Camera housing cable | E17: =IFERROR(VLOOKUP($B17,자재리스트!$B$4:$M$92,4,FALSE),) -> 2세대 카메라하우징 케이블 | F17: =IFERROR(VLOOKUP($B17,자재리스트!$B$4:$M$92,5,FALSE),) -> - | G17: =IFERROR(VLOOKUP($B17,자재리스트!$B$4:$M$92,6,FALSE),) -> 한국 | H17: =IFERROR(VLOOKUP($B17,자재리스트!$B$4:$M$92,7,FALSE),) -> 개 | I17: 6 | J17: =IFERROR(VLOOKUP($B17,자재리스트!$B$4:$M$92,8,FALSE),) -> KRW | K17: =IFERROR(VLOOKUP($B17,자재리스트!$B$4:$M$92,9,FALSE),) -> 211840 | L17: =I17*K17 -> 1271040 | M17: =IFERROR(VLOOKUP($B17,자재리스트!$B$4:$M$92,10,FALSE),) -> 미림테크놀러지 | N17: =IFERROR(VLOOKUP($B17,자재리스트!$B$4:$M$92,11,FALSE),) -> 거래명세서 | O17: =IFERROR(VLOOKUP($B17,자재리스트!$B$4:$M$92,12,FALSE),) -> -
A18: 8 | B18: SC0018 | C18: =IFERROR(VLOOKUP($B18,자재리스트!$B$4:$M$92,2,FALSE),) -> EO Camera | E18: =IFERROR(VLOOKUP($B18,자재리스트!$B$4:$M$92,4,FALSE),) -> 광학 카메라(4K) | F18: =IFERROR(VLOOKUP($B18,자재리스트!$B$4:$M$92,5,FALSE),) -> - | G18: =IFERROR(VLOOKUP($B18,자재리스트!$B$4:$M$92,6,FALSE),) -> 한국 | H18: =IFERROR(VLOOKUP($B18,자재리스트!$B$4:$M$92,7,FALSE),) -> 세트 | I18: 1 | J18: =IFERROR(VLOOKUP($B18,자재리스트!$B$4:$M$92,8,FALSE),) -> KRW | K18: =IFERROR(VLOOKUP($B18,자재리스트!$B$4:$M$92,9,FALSE),) -> 2079000 | L18: =I18*K18 -> 2079000 | M18: =IFERROR(VLOOKUP($B18,자재리스트!$B$4:$M$92,10,FALSE),) -> 아르게스마린 | N18: =IFERROR(VLOOKUP($B18,자재리스트!$B$4:$M$92,11,FALSE),) -> 거래명세서 | O18: =IFERROR(VLOOKUP($B18,자재리스트!$B$4:$M$92,12,FALSE),) -> w. IR Ip-board, EO glass, Receptacle harness, Waterproof cap
A19: 9 | B19: SC0002 | C19: =IFERROR(VLOOKUP($B19,자재리스트!$B$4:$M$92,2,FALSE),) -> IR camera | E19: =IFERROR(VLOOKUP($B19,자재리스트!$B$4:$M$92,4,FALSE),) -> 열화상 카메라 | F19: =IFERROR(VLOOKUP($B19,자재리스트!$B$4:$M$92,5,FALSE),) -> - | G19: =IFERROR(VLOOKUP($B19,자재리스트!$B$4:$M$92,6,FALSE),) -> 미국 | H19: =IFERROR(VLOOKUP($B19,자재리스트!$B$4:$M$92,7,FALSE),) -> 개 | I19: 3 | J19: =IFERROR(VLOOKUP($B19,자재리스트!$B$4:$M$92,8,FALSE),) -> KRW | K19: =IFERROR(VLOOKUP($B19,자재리스트!$B$4:$M$92,9,FALSE),) -> 2487523 | L19: =I19*K19 -> 7462569 | M19: =IFERROR(VLOOKUP($B19,자재리스트!$B$4:$M$92,10,FALSE),) -> IRKEN/FLIR | N19: =IFERROR(VLOOKUP($B19,자재리스트!$B$4:$M$92,11,FALSE),) -> 거래명세서 | O19: =IFERROR(VLOOKUP($B19,자재리스트!$B$4:$M$92,12,FALSE),) -> w. VPC KIT
A20: 10 | B20: SC0019 | C20: =IFERROR(VLOOKUP($B20,자재리스트!$B$4:$M$92,2,FALSE),) -> IR camera window | E20: =IFERROR(VLOOKUP($B20,자재리스트!$B$4:$M$92,4,FALSE),) -> 열화상 카메라 윈도우 | F20: =IFERROR(VLOOKUP($B20,자재리스트!$B$4:$M$92,5,FALSE),) -> - | G20: =IFERROR(VLOOKUP($B20,자재리스트!$B$4:$M$92,6,FALSE),) -> 중국 | H20: =IFERROR(VLOOKUP($B20,자재리스트!$B$4:$M$92,7,FALSE),) -> 개 | I20: 3 | J20: =IFERROR(VLOOKUP($B20,자재리스트!$B$4:$M$92,8,FALSE),) -> KRW | K20: =IFERROR(VLOOKUP($B20,자재리스트!$B$4:$M$92,9,FALSE),) -> 279889 | L20: =I20*K20 -> 839667 | M20: =IFERROR(VLOOKUP($B20,자재리스트!$B$4:$M$92,10,FALSE),) -> 센서캠 | N20: =IFERROR(VLOOKUP($B20,자재리스트!$B$4:$M$92,11,FALSE),) -> 거래명세서 | O20: =IFERROR(VLOOKUP($B20,자재리스트!$B$4:$M$92,12,FALSE),) -> 2세대 용 (직경 45mm)
A21: 11 | B21: SZ0007 | C21: =IFERROR(VLOOKUP($B21,자재리스트!$B$4:$M$92,2,FALSE),) -> Main rack | E21: =IFERROR(VLOOKUP($B21,자재리스트!$B$4:$M$92,4,FALSE),) -> 서버/HUB 등 설치용 Rack | F21: =IFERROR(VLOOKUP($B21,자재리스트!$B$4:$M$92,5,FALSE),) -> - | G21: =IFERROR(VLOOKUP($B21,자재리스트!$B$4:$M$92,6,FALSE),) -> 한국 | H21: =IFERROR(VLOOKUP($B21,자재리스트!$B$4:$M$92,7,FALSE),) -> 개 | I21: 1 | J21: =IFERROR(VLOOKUP($B21,자재리스트!$B$4:$M$92,8,FALSE),) -> KRW | K21: =IFERROR(VLOOKUP($B21,자재리스트!$B$4:$M$92,9,FALSE),) -> 3900000 | L21: =I21*K21 -> 3900000 | M21: =IFERROR(VLOOKUP($B21,자재리스트!$B$4:$M$92,10,FALSE),) -> MRC | N21: =IFERROR(VLOOKUP($B21,자재리스트!$B$4:$M$92,11,FALSE),) -> 거래명세서 | O21: =IFERROR(VLOOKUP($B21,자재리스트!$B$4:$M$92,12,FALSE),) -> -
A22: 12 | B22: SB0002 | C22: =IFERROR(VLOOKUP($B22,자재리스트!$B$4:$M$92,2,FALSE),) -> Network switch | E22: =IFERROR(VLOOKUP($B22,자재리스트!$B$4:$M$92,4,FALSE),) -> 허브 (선급인증품) | F22: =IFERROR(VLOOKUP($B22,자재리스트!$B$4:$M$92,5,FALSE),) -> - | G22: =IFERROR(VLOOKUP($B22,자재리스트!$B$4:$M$92,6,FALSE),) -> 한국 | H22: =IFERROR(VLOOKUP($B22,자재리스트!$B$4:$M$92,7,FALSE),) -> 개 | I22: 2 | J22: =IFERROR(VLOOKUP($B22,자재리스트!$B$4:$M$92,8,FALSE),) -> KRW | K22: =IFERROR(VLOOKUP($B22,자재리스트!$B$4:$M$92,9,FALSE),) -> 1596000 | L22: =I22*K22 -> 3192000 | M22: =IFERROR(VLOOKUP($B22,자재리스트!$B$4:$M$92,10,FALSE),) -> 여의시스템 | N22: =IFERROR(VLOOKUP($B22,자재리스트!$B$4:$M$92,11,FALSE),) -> 거래명세서 | O22: =IFERROR(VLOOKUP($B22,자재리스트!$B$4:$M$92,12,FALSE),) -> -
... A31: 21 | B31: SB0025 | C31: =IFERROR(VLOOKUP($B31,자재리스트!$B$4:$M$92,2,FALSE),) -> UNO2-PS-1AC-24DC-240W | E31: =IFERROR(VLOOKUP($B31,자재리스트!$B$4:$M$92,4,FALSE),) -> POE SWITCH 용 240W 파워 서플라이 | F31: =IFERROR(VLOOKUP($B31,자재리스트!$B$4:$M$92,5,FALSE),) -> - | G31: =IFERROR(VLOOKUP($B31,자재리스트!$B$4:$M$92,6,FALSE),) -> 한국 | H31: =IFERROR(VLOOKUP($B31,자재리스트!$B$4:$M$92,7,FALSE),) -> 개 | I31: 1 | J31: =IFERROR(VLOOKUP($B31,자재리스트!$B$4:$M$92,8,FALSE),) -> KRW | K31: =IFERROR(VLOOKUP($B31,자재리스트!$B$4:$M$92,9,FALSE),) -> 190000 | L31: =I31*K31 -> 190000 | M31: =IFERROR(VLOOKUP($B31,자재리스트!$B$4:$M$92,10,FALSE),) -> 세종전자 | N31: =IFERROR(VLOOKUP($B31,자재리스트!$B$4:$M$92,11,FALSE),) -> 거래명세서 | O31: =IFERROR(VLOOKUP($B31,자재리스트!$B$4:$M$92,12,FALSE),) -> 0
C32: ※ 자유무역협정의 이행을 위한, 원산지 증명서 관련업무 제출을 위하여 작성, 확인합니다.
C33: 작성자: ( 서명 )

Sheet BOM_(신조) HiNAS SVM
A2: 소요부품(자재) 명세서(Bill of Materials)
A4: □ 완제품 품명 | C4: : | D4: (신조) HiNAS SVM
A5: □ HS CODE | C5: : | D5: BS
A6: □ 적용협정 | C6: :
A7: □ 원산지결정기준 | C7: :
A8: □ 원자재 사용내역
A10: 연번 | B10: 자재관리코드 | C10: 품명(자재명) | E10: 기능 및 용도 | F10: 세번부호 (HS No) | G10: 원산지 | H10: 단위 | I10: 소요량 | J10: 통화 | K10: 단가 | L10: 가격 | M10: 구매처 | N10: 입증서류 | O10: 비고
