Workbook
Name CommentList: CommentMaster[표시]

Sheet ABS
B2: Status of Product Delivery(ABS)
B4: 호선 | C4: Product | D4: FAT Date | E4: Flag | F4: Yard | G4: Inspector | H4: Avikus D/L | I4: S/N | J4: FAT 상태 | K4: Comment 진행 | L4: 완료율 | M4: 비고
A5: 1 | B5: 3449 | C5: Control/DOM | D5: 46014 | E5: LIBERIA | F5: HHI | G5: - | J5: FAT 진행하지 않음 | K5: =COUNTIFS(Comments!$A:$A,B5,Comments!$C:$C,"완료") & " / " & COUNTIFS(Comments!$A:$A,B5,Comments!$B:$B,"<>") -> 0 / 0 | L5: =IFERROR(COUNTIFS(Comments!$A:$A,B5,Comments!$C:$C,"완료")/COUNTIFS(Comments!$A:$A,B5,Comments!$B:$B,"<>"),0) -> 0
A6: 2 | B6: 3495 | C6: Control/DOM | D6: 46014 | E6: MARSHALL | F6: HHI | G6: jejeong@eagle.or | J6: FAT 진행완료 | K6: =COUNTIFS(Comments!$A:$A,B6,Comments!$C:$C,"완료") & " / " & COUNTIFS(Comments!$A:$A,B6,Comments!$B:$B,"<>") -> 2 / 4 | L6: =IFERROR(COUNTIFS(Comments!$A:$A,B6,Comments!$C:$C,"완료")/COUNTIFS(Comments!$A:$A,B6,Comments!$B:$B,"<>"),0) -> 0.5
A7: 3 | B7: 3510 | C7: Control/DOM | D7: 46058 | E7: MARSHALL | F7: HHI | G7: KSChang@eagle.org | J7: FAT 진행완료 | K7: =COUNTIFS(Comments!$A:$A,B7,Comments!$C:$C,"완료") & " / " & COUNTIFS(Comments!$A:$A,B7,Comments!$B:$B,"<>") -> 0 / 2 | L7: =IFERROR(COUNTIFS(Comments!$A:$A,B7,Comments!$C:$C,"완료")/COUNTIFS(Comments!$A:$A,B7,Comments!$B:$B,"<>"),0) -> 0
A8: 4 | B8: 8265 | C8: Control/DOM | D8: 46058 | E8: MARSHALL | F8: HSHI | G8: KSChang@eagle.org | J8: FAT 진행완료 | K8: =COUNTIFS(Comments!$A:$A,B8,Comments!$C:$C,"완료") & " / " & COUNTIFS(Comments!$A:$A,B8,Comments!$B:$B,"<>") -> 1 / 4 | L8: =IFERROR(COUNTIFS(Comments!$A:$A,B8,Comments!$C:$C,"완료")/COUNTIFS(Comments!$A:$A,B8,Comments!$B:$B,"<>"),0) -> 0.25
A9: 5 | B9: 3531 | C9: Control/DOM | D9: 46133 | E9: MARSHALL | F9: HHI | G9: junkim@eagle.org | J9: FAT 진행완료 | K9: =COUNTIFS(Comments!$A:$A,B9,Comments!$C:$C,"완료") & " / " & COUNTIFS(Comments!$A:$A,B9,Comments!$B:$B,"<>") -> 1 / 5 | L9: =IFERROR(COUNTIFS(Comments!$A:$A,B9,Comments!$C:$C,"완료")/COUNTIFS(Comments!$A:$A,B9,Comments!$B:$B,"<>"),0) -> 0.2
A10: 6 | B10: 3532 | C10: Control/DOM | D10: 46133 | E10: MARSHALL | F10: HHI | G10: junkim@eagle.org | J10: FAT 진행완료 | K10: =COUNTIFS(Comments!$A:$A,B10,Comments!$C:$C,"완료") & " / " & COUNTIFS(Comments!$A:$A,B10,Comments!$B:$B,"<>") -> 1 / 5 | L10: =IFERROR(COUNTIFS(Comments!$A:$A,B10,Comments!$C:$C,"완료")/COUNTIFS(Comments!$A:$A,B10,Comments!$B:$B,"<>"),0) -> 0.2
A11: 7 | B11: 2946 | C11: Control/DOM | D11: 46134 | E11: LIBERIA | F11: HMD | G11: junkim@eagle.org | J11: FAT 진행완료 | K11: =COUNTIFS(Comments!$A:$A,B11,Comments!$C:$C,"완료") & " / " & COUNTIFS(Comments!$A:$A,B11,Comments!$B:$B,"<>") -> 1 / 6 | L11: =IFERROR(COUNTIFS(Comments!$A:$A,B11,Comments!$C:$C,"완료")/COUNTIFS(Comments!$A:$A,B11,Comments!$B:$B,"<>"),0) -> 0.16666667
A12: 8 | B12: 8441 | C12: Control/DOM | D12: 46134 | E12: PANAMA | F12: HMD | G12: junkim@eagle.org | J12: FAT 진행완료 | K12: =COUNTIFS(Comments!$A:$A,B12,Comments!$C:$C,"완료") & " / " & COUNTIFS(Comments!$A:$A,B12,Comments!$B:$B,"<>") -> 2 / 5 | L12: =IFERROR(COUNTIFS(Comments!$A:$A,B12,Comments!$C:$C,"완료")/COUNTIFS(Comments!$A:$A,B12,Comments!$B:$B,"<>"),0) -> 0.4
A13: 9 | B13: 4300 | C13: Control/DOM | D13: 46154 | E13: MARSHALL | F13: HMD | G13: junkim@eagle.org | J13: FAT 진행완료 | K13: =COUNTIFS(Comments!$A:$A,B13,Comments!$C:$C,"완료") & " / " & COUNTIFS(Comments!$A:$A,B13,Comments!$B:$B,"<>") -> 1 / 5 | L13: =IFERROR(COUNTIFS(Comments!$A:$A,B13,Comments!$C:$C,"완료")/COUNTIFS(Comments!$A:$A,B13,Comments!$B:$B,"<>"),0) -> 0.2
A14: 10 | B14: 4299 | C14: Control/DOM | D14: 46056 | E14: CAPITAL | F14: HSHI | G14: junkim@eagle.org | J14: FAT 진행완료 | K14: =COUNTIFS(Comments!$A:$A,B14,Comments!$C:$C,"완료") & " / " & COUNTIFS(Comments!$A:$A,B14,Comments!$B:$B,"<>") -> 1 / 5 | L14: =IFERROR(COUNTIFS(Comments!$A:$A,B14,Comments!$C:$C,"완료")/COUNTIFS(Comments!$A:$A,B14,Comments!$B:$B,"<>"),0) -> 0.2
A15: 11 | B15: J001 | C15: Control/DOM | D15: 46155 | E15: LIBERIA | F15: HMD | G15: yna@eagle.org | J15: FAT 진행완료 | K15: =COUNTIFS(Comments!$A:$A,B15,Comments!$C:$C,"완료") & " / " & COUNTIFS(Comments!$A:$A,B15,Comments!$B:$B,"<>") -> 0 / 2 | L15: =IFERROR(COUNTIFS(Comments!$A:$A,B15,Comments!$C:$C,"완료")/COUNTIFS(Comments!$A:$A,B15,Comments!$B:$B,"<>"),0) -> 0
A16: 12 | B16: J002 | C16: Control/DOM | D16: 45980 | E16: LIBERIA | F16: HMD | G16: kschang@eagle.org | J16: FAT 진행완료 | K16: =COUNTIFS(Comments!$A:$A,B16,Comments!$C:$C,"완료") & " / " & COUNTIFS(Comments!$A:$A,B16,Comments!$B:$B,"<>") -> 0 / 2 | L16: =IFERROR(COUNTIFS(Comments!$A:$A,B16,Comments!$C:$C,"완료")/COUNTIFS(Comments!$A:$A,B16,Comments!$B:$B,"<>"),0) -> 0
A17: 13 | B17: 3469 | C17: Control | G17: - | J17: FAT 진행하지 않음 | K17: =COUNTIFS(Comments!$A:$A,B17,Comments!$C:$C,"완료") & " / " & COUNTIFS(Comments!$A:$A,B17,Comments!$B:$B,"<>") -> 0 / 1 | L17: =IFERROR(COUNTIFS(Comments!$A:$A,B17,Comments!$C:$C,"완료")/COUNTIFS(Comments!$A:$A,B17,Comments!$B:$B,"<>"),0) -> 0 | M17: 설계 미승인으로 미신청

Sheet Comments
A1: 호선 | B1: Comment 내용 | C1: 상태 | D1: 담당자 | E1: 등록일 | F1: 완료일 | G1: 비고 | H1: 진행률
A2: 3495 | B2: ▼ 3495호선 Comments | H2: =IFERROR(TEXT(COUNTIFS(C3:C5,"완료")/COUNTIF(B3:B5,"<>"),"0%"),"0%") & " (" & COUNTIFS(C3:C5,"완료") & "/" & COUNTIF(B3:B5,"<>") & ")" -> 67% (2/3)
A3: 3495 | B3: ELEC-0336 / S/T or OBT Surveyor 참석 | C3: 완료
A4: 3495 | B4: ELEC-0337 / S/T or OBTpower fail test | C4: 완료
A5: 3495 | B5: ELEC-0338 / OBT, S/T, FAT 결과물 Flag 제출 | C5: 진행중 | D5: 엄선준 | E5: 26.05.18 | G5: ABS에게 문서 제출 예정
A6: 3510 | B6: ▼ 3510호선 Comments | H6: =IFERROR(TEXT(COUNTIFS(C7:C7,"완료")/COUNTIF(B7:B7,"<>"),"0%"),"0%") & " (" & COUNTIFS(C7:C7,"완료") & "/" & COUNTIF(B7:B7,"<>") & ")" -> 0% (0/1)
A7: 3510 | B7: ELEC-0211 / S/T or OBT Surveyor 참석 | C7: OBT 전
A8: 8265 | B8: ▼ 8265호선 Comments | H8: =IFERROR(TEXT(COUNTIFS(C9:C11,"완료")/COUNTIF(B9:B11,"<>"),"0%"),"0%") & " (" & COUNTIFS(C9:C11,"완료") & "/" & COUNTIF(B9:B11,"<>") & ")" -> 33% (1/3)
A9: 8265 | B9: ELEC-0169 / OBT, S/T, FAT 결과물 Flag 제출 | C9: OBT 전
A10: 8265 | B10: ELEC-0170 / S/T or OBT Surveyor 참석 | C10: OBT 전
A11: 8265 | B11: ELEC-0171 / HiNAS Control 도면 제공 | C11: 완료 | G11: ABS Reply로 closed
A12: 3531 | B12: ▼ 3531호선 Comments | H12: =IFERROR(TEXT(COUNTIFS(C13:C16,"완료")/COUNTIF(B13:B16,"<>"),"0%"),"0%") & " (" & COUNTIFS(C13:C16,"완료") & "/" & COUNTIF(B13:B16,"<>") & ")" -> 25% (1/4)
A13: 3531 | B13: ELEC-0130 / S/T or OBT Surveyor 참석 | C13: OBT 전 | G13: OBT 11/10 예정
A14: 3531 | B14: ELEC-0131 / OBT, S/T, FAT 결과물 Flag 제출 for 3531,3532 | C14: OBT 전
A15: 3531 | B15: ELEC-0132 / OBT, S/T, FAT 결과물 Flag 제출 for 3503, 3504 | C15: OBT 전
A16: 3531 | B16: ELEC-0133 / IACS UR E27 related to cyber resilience requirements 문서 일치 확인 | C16: 완료 | D16: 최상덕 | F16: 26.04.21 | G16: 메일 전송 완료
A17: 3532 | B17: ▼ 3532호선 Comments | H17: =IFERROR(TEXT(COUNTIFS(C18:C21,"완료")/COUNTIF(B18:B21,"<>"),"0%"),"0%") & " (" & COUNTIFS(C18:C21,"완료") & "/" & COUNTIF(B18:B21,"<>") & ")" -> 25% (1/4)
A18: 3532 | B18: ELEC-0130 / S/T or OBT Surveyor 참석 | C18: OBT 전
A19: 3532 | B19: ELEC-0131 / OBT, S/T, FAT 결과물 Flag 제출 for 3531,3532 | C19: OBT 전
A20: 3532 | B20: ELEC-0132 / OBT, S/T, FAT 결과물 Flag 제출 for 3503, 3504 | C20: OBT 전
A21: 3532 | B21: ELEC-0133 / IACS UR E27 related to cyber resilience requirements 문서 일치 확인 | C21: 완료 | D21: 최상덕 | F21: 26.04.21 | G21: 메일 전송 완료
A22: 2946 | B22: ▼ 2946호선 Comments | H22: =IFERROR(TEXT(COUNTIFS(C23:C27,"완료")/COUNTIF(B23:B27,"<>"),"0%"),"0%") & " (" & COUNTIFS(C23:C27,"완료") & "/" & COUNTIF(B23:B27,"<>") & ")" -> 20% (1/5)
A23: 2946 | B23: ELEC-0170 / 문서 제출 요청(Quality Plan, System description, Management of proedure) | C23: 진행중 | D23: 엄선준
A24: 2946 | B24: ELEC-0171 / 문서 제출 요청(CBS Inventory,Topology diagram) | C24: 진행중 | D24: 엄선준
A25: 2946 | B25: ELEC-0172 / 문서 제출 요청(FAT) | C25: 완료 | D25: 우승현 | F25: 26.04.28
A26: 2946 | B26: ELEC-0173 / OBT, S/T, FAT 결과물 Flag 제출 | C26: OBT 전
A27: 2946 | B27: ELEC-0174 / S/T or OBT Surveyor 참석 | C27: OBT 전
A28: 8441 | B28: ▼ 8441호선 Comments | H28: =IFERROR(TEXT(COUNTIFS(C29:C32,"완료")/COUNTIF(B29:B32,"<>"),"0%"),"0%") & " (" & COUNTIFS(C29:C32,"완료") & "/" & COUNTIF(B29:B32,"<>") & ")" -> 50% (2/4)
A29: 8441 | B29: ELEC-0250 / IACS UR E27 related to cyber resilience requirements 문서 일치 확인 | C29: 완료 | D29: 우승현 | F29: 26.04.28
A30: 8441 | B30: ELEC-0251 / S/T or OBTpower fail test | C30: 완료 | D30: 정상욱 | G30: OBT 문서 Power Fail Test
A31: 8441 | B31: ELEC-0252 / OBT, S/T, FAT 결과물 Flag 제출 | C31: OBT 전
A32: 8441 | B32: ELEC-0253 / S/T or OBT Surveyor 참석 | C32: OBT 전
A33: 4300 | B33: ▼ 4300호선 Comments | H33: =IFERROR(TEXT(COUNTIFS(C34:C37,"완료")/COUNTIF(B34:B37,"<>"),"0%"),"0%") & " (" & COUNTIFS(C34:C37,"완료") & "/" & COUNTIF(B34:B37,"<>") & ")" -> 25% (1/4)
A34: 4300 | B34: ELEC-0119 / IACS UR E27 related to cyber resilience requirements 문서 일치 확인 | C34: 진행중 | D34: 우승현
A35: 4300 | B35: ELEC-0120 / S/T or OBT Surveyor 참석 | C35: OBT 전
A36: 4300 | B36: ELEC-0121 / S/T or OBTpower fail test | C36: 완료 | D36: 정상욱 | G36: OBT 문서 Power Fail Test
A37: 4300 | B37: ELEC-0122 / OBT, S/T, FAT 결과물 Flag 제출 | C37: OBT 전
A38: 4299 | B38: ▼ 4299호선 Comments | H38: =IFERROR(TEXT(COUNTIFS(C39:C42,"완료")/COUNTIF(B39:B42,"<>"),"0%"),"0%") & " (" & COUNTIFS(C39:C42,"완료") & "/" & COUNTIF(B39:B42,"<>") & ")" -> 25% (1/4)
A39: 4299 | B39: ELEC-0119 / IACS UR E27 related to cyber resilience requirements 문서 일치 확인 | C39: 진행중 | D39: 우승현
A40: 4299 | B40: ELEC-0120 / S/T or OBT Surveyor 참석 | C40: OBT 전
...

Sheet Comment Master
A1: 코드 | B1: Comment 내용 | C1: 카테고리 | D1: 비고 | E1: 표시
A2: ELEC-0119 | B2: IACS UR E27 related to cyber resilience requirements 문서 일치 확인 | C2: Techincal | D2: 4299~4304, 4309 | E2: =CommentMaster[[#This Row],[코드]] & " / " & CommentMaster[[#This Row],[Comment 내용]] -> ELEC-0119 / IACS UR E27 related to cyber resilience requirements 문서 일치 확인
A3: ELEC-0120 | B3: S/T or OBT Surveyor 참석 | C3: Surveyor | D3: 4299~4304, 4309 | E3: =CommentMaster[[#This Row],[코드]] & " / " & CommentMaster[[#This Row],[Comment 내용]] -> ELEC-0120 / S/T or OBT Surveyor 참석
A4: ELEC-0121 | B4: S/T or OBTpower fail test | C4: Techincal | D4: 4299~4304, 4309 | E4: =CommentMaster[[#This Row],[코드]] & " / " & CommentMaster[[#This Row],[Comment 내용]] -> ELEC-0121 / S/T or OBTpower fail test
A5: ELEC-0122 | B5: OBT, S/T, FAT 결과물 Flag 제출 | C5: Techincal | D5: 4299~4304, 4309 | E5: =CommentMaster[[#This Row],[코드]] & " / " & CommentMaster[[#This Row],[Comment 내용]] -> ELEC-0122 / OBT, S/T, FAT 결과물 Flag 제출
A6: ELEC-0336 | B6: S/T or OBT Surveyor 참석 | C6: Surveyor | D6: 3493~3495 | E6: =CommentMaster[[#This Row],[코드]] & " / " & CommentMaster[[#This Row],[Comment 내용]] -> ELEC-0336 / S/T or OBT Surveyor 참석
A7: ELEC-0337 | B7: S/T or OBTpower fail test | C7: Techincal | D7: 3493~3495 | E7: =CommentMaster[[#This Row],[코드]] & " / " & CommentMaster[[#This Row],[Comment 내용]] -> ELEC-0337 / S/T or OBTpower fail test
A8: ELEC-0338 | B8: OBT, S/T, FAT 결과물 Flag 제출 | C8: Techincal | D8: 3493~3495 | E8: =CommentMaster[[#This Row],[코드]] & " / " & CommentMaster[[#This Row],[Comment 내용]] -> ELEC-0338 / OBT, S/T, FAT 결과물 Flag 제출
A9: ELEC-0211 | B9: S/T or OBT Surveyor 참석 | C9: Surveyor | D9: 3509~3510 | E9: =CommentMaster[[#This Row],[코드]] & " / " & CommentMaster[[#This Row],[Comment 내용]] -> ELEC-0211 / S/T or OBT Surveyor 참석
A10: ELEC-0169 | B10: OBT, S/T, FAT 결과물 Flag 제출 | C10: Techincal | D10: 8264~8273 | E10: =CommentMaster[[#This Row],[코드]] & " / " & CommentMaster[[#This Row],[Comment 내용]] -> ELEC-0169 / OBT, S/T, FAT 결과물 Flag 제출
A11: ELEC-0170 | B11: S/T or OBT Surveyor 참석 | C11: Surveyor | D11: 8264~8273, 2943, 2944, 2946, S597 | E11: =CommentMaster[[#This Row],[코드]] & " / " & CommentMaster[[#This Row],[Comment 내용]] -> ELEC-0170 / S/T or OBT Surveyor 참석
A12: ELEC-0171 | B12: HiNAS Control 도면 제공 | C12: Techincal | D12: 8264~8273 | E12: =CommentMaster[[#This Row],[코드]] & " / " & CommentMaster[[#This Row],[Comment 내용]] -> ELEC-0171 / HiNAS Control 도면 제공
A13: ELEC-0130 | B13: S/T or OBT Surveyor 참석 | C13: Surveyor | D13: 3531~3532 | E13: =CommentMaster[[#This Row],[코드]] & " / " & CommentMaster[[#This Row],[Comment 내용]] -> ELEC-0130 / S/T or OBT Surveyor 참석
... A26: ELEC-0101 | B26: S/T or OBT Surveyor 참석 | C26: Surveyor | D26: J001~J004 | E26: =CommentMaster[[#This Row],[코드]] & " / " & CommentMaster[[#This Row],[Comment 내용]] -> ELEC-0101 / S/T or OBT Surveyor 참석
